Workbook
Name DRY: #REF!
Name DRY: #REF!
Name dryx: #REF!
Name WET: #REF!
Name WET: #REF!
Name WET: #REF!

Sheet Cal Certificate
N2: `
C5: Calibration Certificate
R7: Certificate No.: | V7: =CONCATENATE("25-",DataSheet!L5,DataSheet!N5,DataSheet!O5,DataSheet!AN5," ","Rev.00") -> 25- Rev.00
C9: Customer : | O9: Location of Calibration :
D10: =DataSheet!H23 -> 0 | P10: =IF(DataSheet!AE23="x","SONJU ENGINEERING SERVICES",D10) -> SONJU ENGINEERING SERVICES
D11: =DataSheet!H25 -> 0 | P11: =DataSheet!AE27 -> Electrical Calibration Area
C14: Manufacturer: | H14: =DataSheet!K9 -> Fluke | O14: Description: | T14: =DataSheet!K7 -> True RMS Digital Multimeter
C15: Model No: | H15: =DataSheet!K11 -> 289 | O15: Options Installed: | T15: =DataSheet!AL11 -> none
C16: Serial No: | H16: =DataSheet!K13 -> 0 | O16: Customer Asset No: | T16: =DataSheet!AL15 -> 0
C17: Calibration Date: | H17: =DataSheet!AL9 -> 0 | O17: Work Order No.: | T17: =DataSheet!L5 -> 0
C18: Received Date: | H18: =DataSheet!AL7 -> 0 | O18: Customer P.O.: | T18: =DataSheet!AL13 -> none
C19: Temperature: | H19: =IF(DataSheet!AE23="x","23 °C ± 5 °C",CONCATENATE(ROUND(AVERAGE(DataSheet!I39:J40),1)," ","°C")) -> 23 °C ± 5 °C | O19: Humidity: | T19: =IF(DataSheet!AE23="x","55 %rh ± 15 %rh",CONCATENATE(ROUND(AVERAGE(DataSheet!R39:S40),1)," ","%rh")) -> 55 %rh ± 15 %rh
C22: Cal Method / Procedure :
C23: =DataSheet!AB38 -> As per Manufacturer's recommended performance tests procedure for Fluke 287/289 True RMS Digital Multimeter Calibration Manual, February 2008, Rev. 1, 3/09.
C26: This is to certify that the above Measuring and Test Equipment has been calibrated by SONJU Engineering Services in accordance with relevant calibration procedure defined for this instrument.
C29: Uncertainty:
C30: The expanded uncertainty of measurement for the results given in this certificate was estimated with a coverage factor of k = 2 at 95% level of confidence. The uncertainties of measurement were calculated using a Budget Worksheet based on JCGM 100:2008 Evaluation of measurement data - Guide to the Expression of Uncertainty in Measurement, 1st edition- 2008.
C34: Traceability:
C35: The instrument was calibrated using reference standard/s traceable to SI Units as maintained by NML-ITDI (Philippines) through SONJU Engineering Services (Philippines).
C38: Reference Standard Used:
D40: Description | J40: Serial No. | P40: Cal Report Ref. | V40: Due Date
D42: =DataSheet!B31 -> Multiproduct Calibrator | J42: =DataSheet!Q31 -> 8100021 | P42: =DataSheet!AB31 -> 24-9973-01ALT Rev.00 | V42: =DataSheet!AO31 -> 45851
C44: Remarks:
C45: 1. The results were the average of three (3) readings and were obtained during the time of calibration and refer only to the particular instrument submitted. Should the instrument be modified or damaged in any way, or develop inconsistent readings, the results may not be valid and the unit will require recalibration.
C48: 2. The user should determine the suitability of this instrument for its intended use.
C49: 3. Preliminary Inspection: No response at low current function.
C50: 4. Nominal values marked with " * " are outside scope of accreditation.
C51: 5. A positive error is to be subtracted to UUT indication and a negative error added to give true value.
C52: 6. As per customer request the next calibration due date is on: | O52: =EDATE(DataSheet!AL9,12) -> 366
E55: =DataSheet!B175 -> 0 | R55: =DataSheet!B178 -> 0
E56: Calibration Officer | R56: Approved Signatory
D58: Issue Date :
C66: Measurement Results:
E68: =DataSheet!F50 -> DC Voltage Test
E69: Range | I69: Nominal Value | M69: Measured Value | Q69: Error | U69: Uncertainty
E71: =DataSheet!F53 -> 50 mV | I71: =CONCATENATE(DataSheet!L53," ",DataSheet!P53) -> 0 mV | M71: =CONCATENATE(DataSheet!AM53," ",DataSheet!P53) -> #DIV/0! | Q71: =CONCATENATE(TEXT(DataSheet!AR53,"0.000")," ",DataSheet!P53) -> #DIV/0! | U71: =CONCATENATE(TEXT(DataSheet!DD53,"0.000 00")," ",DataSheet!DE53) -> #DIV/0!
I72: =CONCATENATE(DataSheet!L54," ",DataSheet!P54) -> 0.025 mV | M72: =CONCATENATE(DataSheet!AM54," ",DataSheet!P54) -> #DIV/0! | Q72: =CONCATENATE(TEXT(DataSheet!AR54,"0.000")," ",DataSheet!P54) -> #DIV/0! | U72: =CONCATENATE(TEXT(DataSheet!DD54,"0.000 0")," ",DataSheet!DE54) -> #DIV/0!
I73: =CONCATENATE(DataSheet!L55," ",DataSheet!P55) -> -0.025 mV | M73: =CONCATENATE(DataSheet!AM55," ",DataSheet!P55) -> #DIV/0! | Q73: =CONCATENATE(TEXT(DataSheet!AR55,"0.000")," ",DataSheet!P55) -> #DIV/0! | U73: =CONCATENATE(TEXT(DataSheet!DD55,"0.000 0")," ",DataSheet!DE55) -> #DIV/0!
I74: =CONCATENATE(DataSheet!L56," ",DataSheet!P56) -> 50 mV | M74: =CONCATENATE(DataSheet!AM56," ",DataSheet!P56) -> #DIV/0! | Q74: =CONCATENATE(TEXT(DataSheet!AR56,"0.000")," ",DataSheet!P56) -> #DIV/0! | U74: =CONCATENATE(TEXT(DataSheet!DD56,"0.000 0")," ",DataSheet!DE56) -> #DIV/0!
E75: =DataSheet!F57 -> 500 mV | I75: =CONCATENATE(DataSheet!L57," ",DataSheet!P57) -> 500 mV | M75: =CONCATENATE(DataSheet!AM57," ",DataSheet!P57) -> #DIV/0! | Q75: =CONCATENATE(TEXT(DataSheet!AR57,"0.00")," ",DataSheet!P57) -> #DIV/0! | U75: =CONCATENATE(TEXT(DataSheet!DD57,"0.000 0")," ",DataSheet!DE57) -> #DIV/0!
...

Sheet DataSheet
B3: CALIBRATION DATASHEET
F5: Work Order No.: | AI5: Technical ID:
B6: Unit Under Calibration
B7: Description | J7: : | K7: True RMS Digital Multimeter | AB7: Received Date | AK7: :
B9: Manufacturer | J9: : | K9: Fluke | AB9: Calibration Date | AK9: :
B11: Model | J11: : | K11: 289 | AB11: Options Installed | AK11: : | AL11: none
B13: Serial Number | J13: : | AB13: Customer P.O. | AK13: : | AL13: none
B15: Range | J15: : | K15: see specification sheet | AB15: Asset Number | AK15: :
B17: Res/Readability | J17: : | K17: see specification sheet | AB17: Accuracy | AK17: : | AL17: see specification sheet
B19: Prev. SES Cal Cert: | J19: : | K19: none | AB19: Previous Technician | AK19: : | AL19: none
B22: Customer Details | AB22: Calibration Location
B23: Company | G23: : | AE23: x | AG23: In-House (SONJU Laboratory)
B25: Address | G25: : | AG25: On-Site Calibration (Please Specify)
AE27: Electrical Calibration Area
B29: Reference Standard/s Used
B30: Description | Q30: Serial No. | AB30: Cal Report Ref. | AO30: Due Date
B31: Multiproduct Calibrator | Q31: 8100021 | AB31: 24-9973-01ALT Rev.00 | AO31: 45851
B32: - | Q32: - | AB32: - | AO32: -
B33: Accessory Used
B34: Description | Q34: Serial No. | AB34: Brand | AO34: Model
B35: - | Q35: - | AB35: - | AO35: -
B36: - | Q36: - | AB36: - | AO36: -
B37: Environmental Condition | AB37: Calibration Method
F38: Temperature | O38: Relative Humidity | AB38: As per Manufacturer's recommended performance tests procedure for Fluke 287/289 True RMS Digital Multimeter Calibration Manual, February 2008, Rev. 1, 3/09.
H39: Start: | K39: oC | Q39: Start: | T39: %rh
H40: End: | K40: oC | Q40: End: | T40: %rh
B42: Observations
AU43: Adjustment
AU44: Needed?
C45: - | AX45: YES
C46: - | AV46: x | AX46: NO
B48: Measurement Results
F50: DC Voltage Test | BX50: Standard | CD50: Standard | CJ50: Unit Under Test | CP50: Unit Under Test | CV50: Expanded Uncertainty | DB50: MINIMUM CMC (2024) | DD50: FINAL UNCERTAINTY DECLARATION
F51: Range | L51: Nominal Value | S51: Frequency | X51: Measured Value | AM51: Average | AR51: Error | BB51: Specs Tolerance | BG51: Upper Limit | BL51: Lower Limit | BQ51: Remarks | BX51: Source | BY51: Uncertainty | CA51: Divisor | CB51: Ui | CD51: Source | CE51: Uncertainty | CG51: Divisor | CH51: Ui | CJ51: Source | CK51: Uncertainty | CM51: Divisor | CN51: Ui | CP51: Source | CQ51: Uncertainty | CS51: Divisor | CT51: Ui | CV51: COMBINED STANDARD | CW51: EFFECTIVE DEGREES | CX51: C. FACTOR, k = student's | CY51: EXPANDED UNCERTAINTY,
X52: 1 | AC52: 2 | AH52: 3 | CV52: UNCERTAINTY, Uc | CW52: OF FREEDOM, Veff | CX52: t for Veff and 95 % C.L. | CY52: U @ 95 % C.L. ±
F53: 50 mV | L53: 0 | P53: mV | S53: - | AM53: =AVERAGE(X53:AL53) -> #DIV/0! | AR53: =AM53-L53 -> #DIV/0! | BB53: =ABS(0.05%*AM53)+20*CK53 -> #DIV/0! | BG53: 0.02 | BL53: -0.02 | BQ53: =IF(AND(AVERAGE(X53:AL53)<=BG53,AVERAGE(X53:AL53)>=BL53),"PASS","FAIL") -> #DIV/0! | BX53: COC | BY53: 0.00031 | BZ53: =P53 -> mV | CA53: 2 | CB53: =BY53/CA53 -> 0.000155 | CD53: Std. Drift | CE53: 0 | CF53: =P53 -> mV | CG53: =SQRT(3) -> 1.7320508 | CH53: =CE53/CG53 -> 0 | CJ53: Readability | CK53: 0.001 | CL53: =P53 -> mV | CM53: =SQRT(12) -> 3.4641016 | CN53: =CK53/CM53 -> 0.00028867513 | CP53: Std. Dev of Reading | CQ53: =STDEV(X53:AL53) -> #DIV/0! | CR53: =P53 -> mV | CS53: =SQRT(3) -> 1.7320508 | CT53: =CQ53/CS53 -> #DIV/0! | CV53: =SQRT(SUMSQ(CT53,CN53,CH53,CB53)) -> #DIV/0! | CW53: =(CV53^4)/(((CT53^4)/2)+((CN53^4)/200)+((CH53^4)/200)+((CB53^4)/200)) -> #DIV/0! | CX53: =ROUND(TINV(0.05,CW53),0) -> #DIV/0! | CY53: =(CV53*CX53) -> #DIV/0! | CZ53: =P53 -> mV | DB53: 0.00078 | DC53: =CZ53 -> mV | DD53: =MAX(DB53,CY53) -> #DIV/0! | DE53: =DC53 -> mV
L54: 0.025 | P54: mV | S54: - | AM54: =AVERAGE(X54:AL54) -> #DIV/0! | AR54: =AM54-L54 -> #DIV/0! | BB54: =ABS(0.05%*AM54)+20*CK54 -> #DIV/0! | BG54: 0.045 | BL54: 0.005 | BQ54: =IF(AND(AVERAGE(X54:AL54)<=BG54,AVERAGE(X54:AL54)>=BL54),"PASS","FAIL") -> #DIV/0! | BX54: COC | BY54: 0.00077 | BZ54: =P54 -> mV | CA54: 2 | CB54: =BY54/CA54 -> 0.000385 | CD54: Std. Drift | CE54: 0 | CF54: =P54 -> mV | CG54: =SQRT(3) -> 1.7320508 | CH54: =CE54/CG54 -> 0 | CJ54: Readability | CK54: 0.001 | CL54: =P54 -> mV | CM54: =SQRT(12) -> 3.4641016 | CN54: =CK54/CM54 -> 0.00028867513 | CP54: Std. Dev of Reading | CQ54: =STDEV(X54:AL54) -> #DIV/0! | CR54: =P54 -> mV | CS54: =SQRT(3) -> 1.7320508 | CT54: =CQ54/CS54 -> #DIV/0! | CV54: =SQRT(SUMSQ(CT54,CN54,CH54,CB54)) -> #DIV/0! | CW54: =(CV54^4)/(((CT54^4)/2)+((CN54^4)/200)+((CH54^4)/200)+((CB54^4)/200)) -> #DIV/0! | CX54: =ROUND(TINV(0.05,CW54),0) -> #DIV/0! | CY54: =(CV54*CX54) -> #DIV/0! | CZ54: =P54 -> mV | DB54: 0.00078 | DC54: =CZ54 -> mV | DD54: =MAX(DB54,CY54) -> #DIV/0! | DE54: =DC54 -> mV
L55: -0.025 | P55: mV | S55: - | AM55: =AVERAGE(X55:AL55) -> #DIV/0! | AR55: =AM55-L55 -> #DIV/0! | BB55: =ABS(0.05%*AM55)+20*CK55 -> #DIV/0! | BG55: -0.005 | BL55: -0.045 | BQ55: =IF(AND(AVERAGE(X55:AL55)<=BG55,AVERAGE(X55:AL55)>=BL55),"PASS","FAIL") -> #DIV/0! | BX55: COC | BY55: 0.00077 | BZ55: =P55 -> mV | CA55: 2 | CB55: =BY55/CA55 -> 0.000385 | CD55: Std. Drift | CE55: 0 | CF55: =P55 -> mV | CG55: =SQRT(3) -> 1.7320508 | CH55: =CE55/CG55 -> 0 | CJ55: Readability | CK55: 0.001 | CL55: =P55 -> mV | CM55: =SQRT(12) -> 3.4641016 | CN55: =CK55/CM55 -> 0.00028867513 | CP55: Std. Dev of Reading | CQ55: =STDEV(X55:AL55) -> #DIV/0! | CR55: =P55 -> mV | CS55: =SQRT(3) -> 1.7320508 | CT55: =CQ55/CS55 -> #DIV/0! | CV55: =SQRT(SUMSQ(CT55,CN55,CH55,CB55)) -> #DIV/0! | CW55: =(CV55^4)/(((CT55^4)/2)+((CN55^4)/200)+((CH55^4)/200)+((CB55^4)/200)) -> #DIV/0! | CX55: =ROUND(TINV(0.05,CW55),0) -> #DIV/0! | CY55: =(CV55*CX55) -> #DIV/0! | CZ55: =P55 -> mV | DB55: 0.00078 | DC55: =CZ55 -> mV | DD55: =MAX(DB55,CY55) -> #DIV/0! | DE55: =DC55 -> mV
L56: 50 | P56: mV | S56: - | AM56: =AVERAGE(X56:AL56) -> #DIV/0! | AR56: =AM56-L56 -> #DIV/0! | BB56: =ABS(0.05%*AM56)+20*CK56 -> #DIV/0! | BG56: 50.045 | BL56: 49.955 | BQ56: =IF(AND(AVERAGE(X56:AL56)<=BG56,AVERAGE(X56:AL56)>=BL56),"PASS","FAIL") -> #DIV/0! | BX56: COC | BY56: 0.00077 | BZ56: =P56 -> mV | CA56: 2 | CB56: =BY56/CA56 -> 0.000385 | CD56: Std. Drift | CE56: 0 | CF56: =P56 -> mV | CG56: =SQRT(3) -> 1.7320508 | CH56: =CE56/CG56 -> 0 | CJ56: Readability | CK56: 0.001 | CL56: =P56 -> mV | CM56: =SQRT(12) -> 3.4641016 | CN56: =CK56/CM56 -> 0.00028867513 | CP56: Std. Dev of Reading | CQ56: =STDEV(X56:AL56) -> #DIV/0! | CR56: =P56 -> mV | CS56: =SQRT(3) -> 1.7320508 | CT56: =CQ56/CS56 -> #DIV/0! | CV56: =SQRT(SUMSQ(CT56,CN56,CH56,CB56)) -> #DIV/0! | CW56: =(CV56^4)/(((CT56^4)/2)+((CN56^4)/200)+((CH56^4)/200)+((CB56^4)/200)) -> #DIV/0! | CX56: =ROUND(TINV(0.05,CW56),0) -> #DIV/0! | CY56: =(CV56*CX56) -> #DIV/0! | CZ56: =P56 -> mV | DB56: 0.00078 | DC56: =CZ56 -> mV | DD56: =MAX(DB56,CY56) -> #DIV/0! | DE56: =DC56 -> mV
F57: 500 mV | L57: 500 | P57: mV | S57: - | AM57: =AVERAGE(X57:AL57) -> #DIV/0! | AR57: =AM57-L57 -> #DIV/0! | BB57: =ABS(0.025%*AM57)+2*CK57 -> #DIV/0! | BG57: 500.15 | BL57: 499.85 | BQ57: =IF(AND(AVERAGE(X57:AL57)<=BG57,AVERAGE(X57:AL57)>=BL57),"PASS","FAIL") -> #DIV/0! | BX57: COC | BY57: 0.0021 | BZ57: =P57 -> mV | CA57: 2 | CB57: =BY57/CA57 -> 0.00105 | CD57: Std. Drift | CE57: 0 | CF57: =P57 -> mV | CG57: =SQRT(3) -> 1.7320508 | CH57: =CE57/CG57 -> 0 | CJ57: Readability | CK57: 0.01 | CL57: =P57 -> mV | CM57: =SQRT(12) -> 3.4641016 | CN57: =CK57/CM57 -> 0.0028867513 | CP57: Std. Dev of Reading | CQ57: =STDEV(X57:AL57) -> #DIV/0! | CR57: =P57 -> mV | CS57: =SQRT(3) -> 1.7320508 | CT57: =CQ57/CS57 -> #DIV/0! | CV57: =SQRT(SUMSQ(CT57,CN57,CH57,CB57)) -> #DIV/0! | CW57: =(CV57^4)/(((CT57^4)/2)+((CN57^4)/200)+((CH57^4)/200)+((CB57^4)/200)) -> #DIV/0! | CX57: =ROUND(TINV(0.05,CW57),0) -> #DIV/0! | CY57: =(CV57*CX57) -> #DIV/0! | CZ57: =P57 -> mV | DB57: 0.0017 | DC57: =CZ57 -> mV | DD57: =MAX(DB57,CY57) -> #DIV/0! | DE57: =DC57 -> mV
...

Sheet Specification
