Workbook
Name DRY: #REF!
Name DRY: #REF!
Name dryx: #REF!
Name WET: #REF!
Name WET: #REF!
Name WET: #REF!

Sheet Cal Certificate
C5: Calibration Certificate
R7: Certificate No.: | V7: =CONCATENATE("25-",DataSheet!L5,DataSheet!N5,DataSheet!O5,DataSheet!AN5," ","Rev.00") -> 25- Rev.00
C9: Customer : | O9: Location of Calibration :
D10: =DataSheet!H23 -> 0 | P10: =IF(DataSheet!AE23="x","SONJU ENGINEERING SERVICES",D10) -> 0
D11: =DataSheet!H25 -> 0 | P11: =DataSheet!AG27 -> Electrical Room
C15: Manufacturer: | H15: =DataSheet!K9 -> Fluke | O15: Description: | T15: =DataSheet!K7 -> Digital Multimeter
C16: Model No: | H16: =DataSheet!K11 -> 114 | O16: Options Installed: | T16: =DataSheet!AL11 -> none
C17: Serial No: | H17: =DataSheet!K13 -> 0 | O17: Customer Asset No: | T17: =DataSheet!AL15 -> 0
C18: Calibration Date: | H18: =DataSheet!AL9 -> 0 | O18: Work Order No.: | T18: =DataSheet!L5 -> 0
C19: Received Date: | H19: =DataSheet!AL7 -> 0 | O19: Customer P.O.: | T19: =DataSheet!AL13 -> none
C20: Temperature: | H20: =IF(DataSheet!AE23="x","23 °C ± 5 °C",CONCATENATE(ROUND(AVERAGE(DataSheet!I37:J38),1)," ","°C")) -> #DIV/0! | O20: Humidity: | T20: =IF(DataSheet!AE23="x","55 %rh ± 15 %rh",CONCATENATE(ROUND(AVERAGE(DataSheet!R37:S38),1)," ","%rh")) -> #DIV/0!
C23: Cal Method / Procedure :
C24: =DataSheet!AB36 -> As per Manufacturer's recommended performance tests procedure for Fluke 114 Digital Multimeter Calibration Information, 1st - rev., September 2006.
C27: This is to certify that the above Measuring and Test Equipment has been calibrated by SONJU Engineering Services in accordance with relevant calibration procedure defined for this instrument.
C30: Uncertainty :
C31: The expanded uncertainty of measurement for the results given in this certificate was estimated with a coverage factor of k = 2 at 95% level of confidence. The uncertainties of measurement were calculated using a budget worksheet based on JCGM 100:2008 Evaluation of measurement data - Guide to the Expression of Uncertainty in Measurement, 1st edition- 2008.
C35: Traceability:
C36: The instrument was calibrated using reference standard/s traceable to SI Units as maintained by NML-ITDI (Philippines) through SONJU Engineering Services (Philippines).
C39: Reference Standard Used:
D41: Description | K41: Serial No. | O41: Cal Report Ref. | V41: Due Date
D43: =DataSheet!B31 -> Multiproduct Calibrator | K43: =DataSheet!Q31 -> 8100021 | O43: =DataSheet!AB31 -> 24-9973-01ALT Rev.00 | V43: =DataSheet!AO31 -> 0
C45: Remarks:
C46: 1. The results are the average of three (3) readings obtained during the time of calibration and refer only to the particular instrument submitted. Should the instrument be modified or damaged in any way, or develop inconsistent readings, the results may not be valid and the unit will require recalibration.
C49: 2. The user should determine the suitability of this instrument for its intended use.
C50: 3. Preliminary Inspection: Satisfactory.
C51: 4. A positive error is to be subtracted to UUT indication and a negative error added to give true value.
C52: 5. As per customer request the next calibration due date is on: | O52: =EDATE(DataSheet!AL9,12) -> 366
E56: =DataSheet!B111 -> 0 | S56: Jennefer S. Ilas
E57: Calibration Officer | S57: Approved Signatory
D59: Issue Date :
D67: Measurement Results:
E69: =DataSheet!F49 -> Resistance Test
E70: Range | I70: Nominal Value | M70: Measured Value | Q70: Error | U70: Uncertainty
E73: =DataSheet!F52 -> 600 Ω | I73: =CONCATENATE(DataSheet!L52," ",DataSheet!P52) -> 0 Ω | M73: =CONCATENATE(TEXT(DataSheet!AM52,"0.0")," ",DataSheet!P52) -> #DIV/0! | Q73: =CONCATENATE(TEXT(DataSheet!AR52,"0.0")," ",DataSheet!P52) -> #DIV/0! | U73: =CONCATENATE(TEXT(DataSheet!DE52,"0.000")," ",DataSheet!DF52) -> #DIV/0!
I74: =CONCATENATE(DataSheet!L53," ",DataSheet!P53) -> 500 Ω | M74: =CONCATENATE(TEXT(DataSheet!AM53,"0.0")," ",DataSheet!P53) -> #DIV/0! | Q74: =CONCATENATE(TEXT(DataSheet!AR53,"0.0")," ",DataSheet!P53) -> #DIV/0! | U74: =CONCATENATE(TEXT(DataSheet!DE53,"0.000")," ",DataSheet!DF53) -> #DIV/0!
E75: =DataSheet!F54 -> 6 kΩ | I75: =CONCATENATE(DataSheet!L54," ",DataSheet!P54) -> 5 kΩ | M75: =CONCATENATE(TEXT(DataSheet!AM54,"0.000")," ",DataSheet!P54) -> #DIV/0! | Q75: =CONCATENATE(TEXT(DataSheet!AR54,"0.000")," ",DataSheet!P54) -> #DIV/0! | U75: =CONCATENATE(TEXT(DataSheet!DE54,"0.000\ 00")," ",DataSheet!DF54) -> #DIV/0!
E76: =DataSheet!F55 -> 60 kΩ | I76: =CONCATENATE(DataSheet!L55," ",DataSheet!P55) -> 50 kΩ | M76: =CONCATENATE(TEXT(DataSheet!AM55,"0.00")," ",DataSheet!P55) -> #DIV/0! | Q76: =CONCATENATE(TEXT(DataSheet!AR55,"0.00")," ",DataSheet!P55) -> #DIV/0! | U76: =CONCATENATE(TEXT(DataSheet!DE55,"0.000\ 0")," ",DataSheet!DF55) -> #DIV/0!
E77: =DataSheet!F56 -> 600 kΩ | I77: =CONCATENATE(DataSheet!L56," ",DataSheet!P56) -> 500 kΩ | M77: =CONCATENATE(TEXT(DataSheet!AM56,"0.0")," ",DataSheet!P56) -> #DIV/0! | Q77: =CONCATENATE(TEXT(DataSheet!AR56,"0.0")," ",DataSheet!P56) -> #DIV/0! | U77: =CONCATENATE(TEXT(DataSheet!DE56,"0.000")," ",DataSheet!DF56) -> #DIV/0!
E78: =DataSheet!F57 -> 6 MΩ | I78: =CONCATENATE(DataSheet!L57," ",DataSheet!P57) -> 5 MΩ | M78: =CONCATENATE(TEXT(DataSheet!AM57,"0.000")," ",DataSheet!P57) -> #DIV/0! | Q78: =CONCATENATE(TEXT(DataSheet!AR57,"0.000")," ",DataSheet!P57) -> #DIV/0! | U78: =CONCATENATE(TEXT(DataSheet!DE57,"0.000\ 00")," ",DataSheet!DF57) -> #DIV/0!
E79: =DataSheet!F58 -> 40 MΩ | I79: =CONCATENATE(DataSheet!L58," ",DataSheet!P58) -> 10 MΩ | M79: =CONCATENATE(TEXT(DataSheet!AM58,"0.00")," ",DataSheet!P58) -> #DIV/0! | Q79: =CONCATENATE(TEXT(DataSheet!AR58,"0.00")," ",DataSheet!P58) -> #DIV/0! | U79: =CONCATENATE(TEXT(DataSheet!DE58,"0.000\ 0")," ",DataSheet!DF58) -> #DIV/0!
...

Sheet DataSheet
B3: CALIBRATION DATASHEET
F5: Work Order No.: | AI5: Technical ID:
B6: Unit Under Calibration
B7: Description | J7: : | K7: Digital Multimeter | AB7: Received Date | AK7: :
B9: Manufacturer | J9: : | K9: Fluke | AB9: Calibration Date | AK9: :
B11: Model | J11: : | K11: 114 | AB11: Options Installed | AK11: : | AL11: none
B13: Serial Number | J13: : | AB13: Customer P.O. | AK13: : | AL13: none
B15: Range | J15: : | K15: See specification sheet | AB15: Asset Number | AK15: :
B17: Res/Readability | J17: : | K17: 3 1/2 digits | AB17: Accuracy | AK17: : | AL17: See specification sheet
B19: Prev. SES Cal Cert: | J19: : | AB19: Previous Technician | AK19: :
B22: Customer Details | AB22: Calibration Location
B23: Company | G23: : | AG23: In-House (SONJU Laboratory)
B25: Address | G25: : | AE25: x | AG25: On-Site Calibration (Please Specify)
AG27: Electrical Room
B29: Reference Standard/s Used
B30: Description | Q30: Serial No. | AB30: Cal Report Ref. | AO30: Due Date
B31: Multiproduct Calibrator | Q31: 8100021 | AB31: 24-9973-01ALT Rev.00
B32: Accessory Used
B33: Description | Q33: Serial No. | AB33: Cal Report Ref. | AO33: Due Date
B34: - | Q34: - | AB34: - | AO34: -
B35: Environmental Condition | AB35: Calibration Method
F36: Temperature | O36: Relative Humidity | AB36: As per Manufacturer's recommended performance tests procedure for Fluke 114 Digital Multimeter Calibration Information, 1st - rev., September 2006.
H37: Start: | K37: oC | Q37: Start: | T37: %rh
H38: End: | K38: oC | Q38: End: | T38: %rh
B40: Observations
C41: none | AU41: Adjustment
AU42: Needed?
AX43: YES
AW44: x | AX44: NO
B46: Measurement Results
F49: Resistance Test | BX49: Standard | CD49: Standard | CJ49: Unit Under Test | CP49: Unit Under Test | CV49: Expanded Uncertainty | DB49: Minimum Approved CMC | DE49: Final Declaration of Uncertainty
F50: Range | L50: Nominal Value | S50: Frequency | X50: Measured Value | AM50: Average | AR50: Error | BB50: Tolerance | BG50: Upper Limit | BL50: Lower Limit | BQ50: Remarks | BX50: Source | BY50: Uncertainty | CA50: Divisor | CB50: Ui | CD50: Source | CE50: Uncertainty | CG50: Divisor | CH50: Ui | CJ50: Source | CK50: Uncertainty | CM50: Divisor | CN50: Ui | CP50: Source | CQ50: Uncertainty | CS50: Divisor | CT50: Ui | CV50: COMBINED STANDARD | CW50: EFFECTIVE DEGREES | CX50: C. FACTOR, k = student's | CY50: EXPANDED UNCERTAINTY,
X51: 1 | AC51: 2 | AH51: 3 | CV51: UNCERTAINTY, Uc | CW51: OF FREEDOM, Veff | CX51: t for Veff and 95 % C.L. | CY51: U @ 95 % C.L. ±
F52: 600 Ω | L52: 0 | P52: Ω | S52: - | AM52: =ROUND(AVERAGE(X52:AL52),1) -> #DIV/0! | AR52: =AM52-L52 -> #DIV/0! | BB52: =ROUND((BG52-L52),1) -> 0.2 | BG52: 0.2 | BL52: 0 | BQ52: =IF(AND(AM52<=BG52,AM52>=BL52),"PASS","FAIL") -> #DIV/0! | BX52: COC | BY52: 7.7e-05 | BZ52: =P52 -> Ω | CA52: 2 | CB52: =BY52/CA52 -> 3.85e-05 | CD52: Annual Drift | CE52: 0 | CF52: =BZ52 -> Ω | CG52: =SQRT(3) -> 1.7320508 | CH52: =CE52/CG52 -> 0 | CJ52: Readability | CK52: 0.1 | CL52: =P52 -> Ω | CM52: =SQRT(12) -> 3.4641016 | CN52: =CK52/CM52 -> 0.028867513 | CP52: Repeatability | CQ52: =_xlfn.STDEV.P(X52:AL52) -> #DIV/0! | CR52: =P52 -> Ω | CS52: =SQRT(3) -> 1.7320508 | CT52: =CQ52/CS52 -> #DIV/0! | CV52: =SQRT(SUMSQ(CT52,CN52,CH52,CB52)) -> #DIV/0! | CW52: =(CV52^4)/(((CT52^4)/2)+((CN52^4)/200)+((CH52^4)/200)+((CB52^4)/200)) -> #DIV/0! | CX52: =ROUND(TINV(0.05,CW52),0) -> #DIV/0! | CY52: =ROUND((CV52*CX52),3) -> #DIV/0! | CZ52: =P52 -> Ω | DB52: 0.0078 | DC52: =CZ52 -> Ω | DE52: =MAX(CY52:DB52) -> #DIV/0! | DF52: =CZ52 -> Ω
F53: 600 Ω | L53: 500 | P53: Ω | S53: - | AM53: =ROUND(AVERAGE(X53:AL53),1) -> #DIV/0! | AR53: =AM53-L53 -> #DIV/0! | BB53: =ROUND((BG53-L53),1) -> 4.7 | BG53: 504.7 | BL53: 495.3 | BQ53: =IF(AND(AM53<=BG53,AM53>=BL53),"PASS","FAIL") -> #DIV/0! | BX53: COC | BY53: 0.003 | BZ53: =P53 -> Ω | CA53: 2 | CB53: =BY53/CA53 -> 0.0015 | CD53: Annual Drift | CE53: 0 | CF53: =BZ53 -> Ω | CG53: =SQRT(3) -> 1.7320508 | CH53: =CE53/CG53 -> 0 | CJ53: Readability | CK53: 0.1 | CL53: =P53 -> Ω | CM53: =SQRT(12) -> 3.4641016 | CN53: =CK53/CM53 -> 0.028867513 | CP53: Repeatability | CQ53: =_xlfn.STDEV.P(X53:AL53) -> #DIV/0! | CR53: =P53 -> Ω | CS53: =SQRT(3) -> 1.7320508 | CT53: =CQ53/CS53 -> #DIV/0! | CV53: =SQRT(SUMSQ(CT53,CN53,CH53,CB53)) -> #DIV/0! | CW53: =(CV53^4)/(((CT53^4)/2)+((CN53^4)/200)+((CH53^4)/200)+((CB53^4)/200)) -> #DIV/0! | CX53: =ROUND(TINV(0.05,CW53),0) -> #DIV/0! | CY53: =ROUND((CV53*CX53),5) -> #DIV/0! | CZ53: =P53 -> Ω | DB53: 0.023 | DC53: =CZ53 -> Ω | DE53: =MAX(CY53:DB53) -> #DIV/0! | DF53: =CZ53 -> Ω
F54: 6 kΩ | L54: 5 | P54: kΩ | S54: - | AM54: =ROUND(AVERAGE(X54:AL54),3) -> #DIV/0! | AR54: =AM54-L54 -> #DIV/0! | BB54: =ROUND((BG54-L54),3) -> 0.046 | BG54: 5.046 | BL54: 4.954 | BQ54: =IF(AND(AM54<=BG54,AM54>=BL54),"PASS","FAIL") -> #DIV/0! | BX54: COC | BY54: 5.5e-05 | BZ54: =P54 -> kΩ | CA54: 2 | CB54: =BY54/CA54 -> 2.75e-05 | CD54: Annual Drift | CE54: 0 | CF54: =BZ54 -> kΩ | CG54: =SQRT(3) -> 1.7320508 | CH54: =CE54/CG54 -> 0 | CJ54: Readability | CK54: 0.001 | CL54: =P54 -> kΩ | CM54: =SQRT(12) -> 3.4641016 | CN54: =CK54/CM54 -> 0.00028867513 | CP54: Repeatability | CQ54: =_xlfn.STDEV.P(X54:AL54) -> #DIV/0! | CR54: =P54 -> kΩ | CS54: =SQRT(3) -> 1.7320508 | CT54: =CQ54/CS54 -> #DIV/0! | CV54: =SQRT(SUMSQ(CT54,CN54,CH54,CB54)) -> #DIV/0! | CW54: =(CV54^4)/(((CT54^4)/2)+((CN54^4)/200)+((CH54^4)/200)+((CB54^4)/200)) -> #DIV/0! | CX54: =ROUND(TINV(0.05,CW54),0) -> #DIV/0! | CY54: =ROUND((CV54*CX54),5) -> #DIV/0! | CZ54: =P54 -> kΩ | DB54: 0.00023 | DC54: =CZ54 -> kΩ | DE54: =MAX(CY54:DB54) -> #DIV/0! | DF54: =CZ54 -> kΩ
F55: 60 kΩ | L55: 50 | P55: kΩ | S55: - | AM55: =ROUND(AVERAGE(X55:AL55),2) -> #DIV/0! | AR55: =AM55-L55 -> #DIV/0! | BB55: =ROUND((BG55-L55),2) -> 0.46 | BG55: 50.46 | BL55: 49.54 | BQ55: =IF(AND(AM55<=BG55,AM55>=BL55),"PASS","FAIL") -> #DIV/0! | BX55: COC | BY55: 0.00081 | BZ55: =P55 -> kΩ | CA55: 2 | CB55: =BY55/CA55 -> 0.000405 | CD55: Annual Drift | CE55: 0 | CF55: =BZ55 -> kΩ | CG55: =SQRT(3) -> 1.7320508 | CH55: =CE55/CG55 -> 0 | CJ55: Readability | CK55: 0.01 | CL55: =P55 -> kΩ | CM55: =SQRT(12) -> 3.4641016 | CN55: =CK55/CM55 -> 0.0028867513 | CP55: Repeatability | CQ55: =_xlfn.STDEV.P(X55:AL55) -> #DIV/0! | CR55: =P55 -> kΩ | CS55: =SQRT(3) -> 1.7320508 | CT55: =CQ55/CS55 -> #DIV/0! | CV55: =SQRT(SUMSQ(CT55,CN55,CH55,CB55)) -> #DIV/0! | CW55: =(CV55^4)/(((CT55^4)/2)+((CN55^4)/200)+((CH55^4)/200)+((CB55^4)/200)) -> #DIV/0! | CX55: =ROUND(TINV(0.05,CW55),0) -> #DIV/0! | CY55: =ROUND((CV55*CX55),4) -> #DIV/0! | CZ55: =P55 -> kΩ | DB55: 0.0015 | DC55: =CZ55 -> kΩ | DE55: =MAX(CY55:DB55) -> #DIV/0! | DF55: =CZ55 -> kΩ
F56: 600 kΩ | L56: 500 | P56: kΩ | S56: - | AM56: =ROUND(AVERAGE(X56:AL56),1) -> #DIV/0! | AR56: =AM56-L56 -> #DIV/0! | BB56: =ROUND((BG56-L56),1) -> 4.6 | BG56: 504.6 | BL56: 495.4 | BQ56: =IF(AND(AM56<=BG56,AM56>=BL56),"PASS","FAIL") -> #DIV/0! | BX56: COC | BY56: 0.0066 | BZ56: =P56 -> kΩ | CA56: 2 | CB56: =BY56/CA56 -> 0.0033 | CD56: Annual Drift | CE56: 0 | CF56: =BZ56 -> kΩ | CG56: =SQRT(3) -> 1.7320508 | CH56: =CE56/CG56 -> 0 | CJ56: Readability | CK56: 0.1 | CL56: =P56 -> kΩ | CM56: =SQRT(12) -> 3.4641016 | CN56: =CK56/CM56 -> 0.028867513 | CP56: Repeatability | CQ56: =_xlfn.STDEV.P(X56:AL56) -> #DIV/0! | CR56: =P56 -> kΩ | CS56: =SQRT(3) -> 1.7320508 | CT56: =CQ56/CS56 -> #DIV/0! | CV56: =SQRT(SUMSQ(CT56,CN56,CH56,CB56)) -> #DIV/0! | CW56: =(CV56^4)/(((CT56^4)/2)+((CN56^4)/200)+((CH56^4)/200)+((CB56^4)/200)) -> #DIV/0! | CX56: =ROUND(TINV(0.05,CW56),0) -> #DIV/0! | CY56: =ROUND((CV56*CX56),4) -> #DIV/0! | CZ56: =P56 -> kΩ | DB56: 0.016 | DC56: =CZ56 -> kΩ | DE56: =MAX(CY56:DB56) -> #DIV/0! | DF56: =CZ56 -> kΩ
F57: 6 MΩ | L57: 5 | P57: MΩ | S57: - | AM57: =ROUND(AVERAGE(X57:AL57),3) -> #DIV/0! | AR57: =AM57-L57 -> #DIV/0! | BB57: =ROUND((BG57-L57),3) -> 0.046 | BG57: 5.046 | BL57: 4.954 | BQ57: =IF(AND(AM57<=BG57,AM57>=BL57),"PASS","FAIL") -> #DIV/0! | BX57: COC | BY57: 0.00048 | BZ57: =P57 -> MΩ | CA57: 2 | CB57: =BY57/CA57 -> 0.00024 | CD57: Annual Drift | CE57: 0 | CF57: =BZ57 -> MΩ | CG57: =SQRT(3) -> 1.7320508 | CH57: =CE57/CG57 -> 0 | CJ57: Readability | CK57: 0.001 | CL57: =P57 -> MΩ | CM57: =SQRT(12) -> 3.4641016 | CN57: =CK57/CM57 -> 0.00028867513 | CP57: Repeatability | CQ57: =_xlfn.STDEV.P(X57:AL57) -> #DIV/0! | CR57: =P57 -> MΩ | CS57: =SQRT(3) -> 1.7320508 | CT57: =CQ57/CS57 -> #DIV/0! | CV57: =SQRT(SUMSQ(CT57,CN57,CH57,CB57)) -> #DIV/0! | CW57: =(CV57^4)/(((CT57^4)/2)+((CN57^4)/200)+((CH57^4)/200)+((CB57^4)/200)) -> #DIV/0! | CX57: =ROUND(TINV(0.05,CW57),0) -> #DIV/0! | CY57: =ROUND((CV57*CX57),4) -> #DIV/0! | CZ57: =P57 -> MΩ | DB57: 0.00053 | DC57: =CZ57 -> MΩ | DE57: =MAX(CY57:DB57) -> #DIV/0! | DF57: =CZ57 -> MΩ
F58: 40 MΩ | L58: 10 | P58: MΩ | S58: - | AM58: =ROUND(AVERAGE(X58:AL58),2) -> #DIV/0! | AR58: =AM58-L58 -> #DIV/0! | BB58: =ROUND((BG58-L58),2) -> 0.52 | BG58: 10.52 | BL58: 9.48 | BQ58: =IF(AND(AM58<=BG58,AM58>=BL58),"PASS","FAIL") -> #DIV/0! | BX58: COC | BY58: 0.00048 | BZ58: =P58 -> MΩ | CA58: 2 | CB58: =BY58/CA58 -> 0.00024 | CD58: Annual Drift | CE58: 0 | CF58: =BZ58 -> MΩ | CG58: =SQRT(3) -> 1.7320508 | CH58: =CE58/CG58 -> 0 | CJ58: Readability | CK58: 0.01 | CL58: =P58 -> MΩ | CM58: =SQRT(12) -> 3.4641016 | CN58: =CK58/CM58 -> 0.0028867513 | CP58: Repeatability | CQ58: =_xlfn.STDEV.P(X58:AL58) -> #DIV/0! | CR58: =P58 -> MΩ | CS58: =SQRT(3) -> 1.7320508 | CT58: =CQ58/CS58 -> #DIV/0! | CV58: =SQRT(SUMSQ(CT58,CN58,CH58,CB58)) -> #DIV/0! | CW58: =(CV58^4)/(((CT58^4)/2)+((CN58^4)/200)+((CH58^4)/200)+((CB58^4)/200)) -> #DIV/0! | CX58: =ROUND(TINV(0.05,CW58),0) -> #DIV/0! | CY58: =ROUND((CV58*CX58),4) -> #DIV/0! | CZ58: =P58 -> MΩ | DB58: 0.00053 | DC58: =CZ58 -> MΩ | DE58: =MAX(CY58:DB58) -> #DIV/0! | DF58: =CZ58 -> MΩ
...

Sheet Specification
