Workbook
Name DRY: #REF!
Name DRY: #REF!
Name dryx: #REF!
Name WET: #REF!
Name WET: #REF!
Name WET: #REF!

Sheet Cal Certificate
C5: Calibration Certificate
R7: Certificate No.: | V7: =CONCATENATE("25-",DataSheet!L5,DataSheet!N5,DataSheet!O5,DataSheet!AN5," ","Rev.00") -> 25- Rev.00
C9: Customer : | O9: Location of Calibration :
D10: =DataSheet!H23 -> 0 | P10: =IF(DataSheet!AE23="x","SONJU ENGINEERING SERVICES",D10) -> SONJU ENGINEERING SERVICES
D11: =DataSheet!H25 -> 0 | P11: =DataSheet!AG27 -> Electrical Calibration Area
C15: Manufacturer: | H15: =DataSheet!K9 -> Fluke | O15: Description: | T15: =DataSheet!K7 -> Digital Multimeter
C16: Model No: | H16: =DataSheet!K11 -> 117 | O16: Options Installed: | T16: =DataSheet!AL11 -> none
C17: Serial No: | H17: =DataSheet!K13 -> 0 | O17: Customer Asset No: | T17: =DataSheet!AL15 -> none
C18: Calibration Date: | H18: =DataSheet!AL9 -> 0 | O18: Work Order No.: | T18: =DataSheet!L5 -> 0
C19: Received Date: | H19: =DataSheet!AL7 -> 0 | O19: Customer P.O.: | T19: =DataSheet!AL13 -> none
C20: Temperature: | H20: =IF(DataSheet!AE23="x","23 °C ± 5 °C",CONCATENATE(ROUND(AVERAGE(DataSheet!I39:J40),1)," ","°C")) -> 23 °C ± 5 °C | O20: Humidity: | T20: =IF(DataSheet!AE23="x","55 %rh ± 15 %rh",CONCATENATE(ROUND(AVERAGE(DataSheet!R39:S40),1)," ","%rh")) -> 55 %rh ± 15 %rh
C22: Cal Method / Procedure :
C23: =DataSheet!AB38 -> As per Manufacturer's recommended performance tests procedure for Fluke 117 Digital Multimeters Calibration Information, 1st - rev., September 2006.
C26: This is to certify that the above Measuring and Test Equipment has been calibrated by SONJU Engineering Services in accordance with relevant calibration procedure defined for this instrument.
C29: Uncertainty :
C30: The expanded uncertainty of measurement for the results given in this certificate was estimated with a coverage factor of k = 2 at 95% level of confidence. The uncertainties of measurement were calculated using a budget worksheet based on JCGM 100:2008 Evaluation of measurement data - Guide to the Expression of Uncertainty in Measurement, 1st edition- 2008.
C34: Traceability: The instrument was calibrated using reference standard/s traceable to SI Units as maintained by NML-ITDI (Philippines) through SONJU Engineering Services (Philippines).
C38: Reference Standard Used:
D40: Description | K40: Serial No. | O40: Cal Report Ref. | V40: Due Date
D42: =DataSheet!B31 -> Multiproduct Calibrator | K42: =DataSheet!Q31 -> 8100021 | O42: =DataSheet!AB31 -> 24-9973-01ALT Rev.00 | V42: =DataSheet!AO31 -> 0
C44: Remarks:
C45: 1. The results were the average of the three (3) readings and were obtained during the time of calibration and refer only to the particular instrument submitted. Should the instrument be modified or damaged in any way, or develop inconsistent readings, the results may not be valid and the unit will require recalibration.
C48: 2. The user should determine the suitability of this instrument for its intended use.
C49: 3. Preliminary Inspection: Satisfactory
C50: 4. Nominal values marked with " * " are outside Scope of Accreditation.
C51: 5. A positve error is to subtracted to the UUT indication and negative error added to give true value.
C52: 6. As per customer request the next calibration due date is on: | P52: =EDATE(DataSheet!AL9,12) -> 366
E54: =DataSheet!B131 -> 0 | S54: Jennefer S. Ilas
E55: Calibration Officer | S55: Approved Signatory
D57: Issue Date :
C65: Measurement Results:
E67: =DataSheet!F50 -> Resistance Test
E68: Range | I68: Nominal Value | M68: Measured Value | Q68: Error | U68: Uncertainty
E70: =DataSheet!F53 -> 600 Ω | I70: =CONCATENATE(DataSheet!L53," ",DataSheet!P53) -> 0 Ω | M70: =CONCATENATE(TEXT(DataSheet!AH53,"0.0")," ",DataSheet!P53) -> #DIV/0! | Q70: =CONCATENATE(TEXT(DataSheet!AM53,"0.0")," ",DataSheet!P53) -> #DIV/0! | U70: =CONCATENATE(TEXT(DataSheet!EL53,"0.000")," ",DataSheet!EH53) -> #DIV/0!
I71: =CONCATENATE(DataSheet!L54," ",DataSheet!P54) -> 500 Ω | M71: =CONCATENATE(TEXT(DataSheet!AH54,"0.0")," ",DataSheet!P54) -> #DIV/0! | Q71: =CONCATENATE(TEXT(DataSheet!AM54,"0.0")," ",DataSheet!P54) -> #DIV/0! | U71: =CONCATENATE(TEXT(DataSheet!EL54,"0.000")," ",DataSheet!EH54) -> #DIV/0!
E72: =DataSheet!F55 -> 6 kΩ | I72: =CONCATENATE(DataSheet!L55," ",DataSheet!P55) -> 5 kΩ | M72: =CONCATENATE(TEXT(DataSheet!AH55,"0.000")," ",DataSheet!P55) -> #DIV/0! | Q72: =CONCATENATE(TEXT(DataSheet!AM55,"0.000")," ",DataSheet!P55) -> #DIV/0! | U72: =CONCATENATE(TEXT(DataSheet!EL55,"0.000 00")," ",DataSheet!EH55) -> #DIV/0!
E73: =DataSheet!F56 -> 60 kΩ | I73: =CONCATENATE(DataSheet!L56," ",DataSheet!P56) -> 50 kΩ | M73: =CONCATENATE(TEXT(DataSheet!AH56,"0.00")," ",DataSheet!P56) -> #DIV/0! | Q73: =CONCATENATE(TEXT(DataSheet!AM56,"0.00")," ",DataSheet!P56) -> #DIV/0! | U73: =CONCATENATE(TEXT(DataSheet!EL56,"0.000 0")," ",DataSheet!EH56) -> #DIV/0!
E74: =DataSheet!F57 -> 600 kΩ | I74: =CONCATENATE(DataSheet!L57," ",DataSheet!P57) -> 500 kΩ | M74: =CONCATENATE(TEXT(DataSheet!AH57,"0.0")," ",DataSheet!P57) -> #DIV/0! | Q74: =CONCATENATE(TEXT(DataSheet!AM57,"0.0")," ",DataSheet!P57) -> #DIV/0! | U74: =CONCATENATE(TEXT(DataSheet!EL57,"0.000")," ",DataSheet!EH57) -> #DIV/0!
E75: =DataSheet!F58 -> 6 MΩ | I75: =CONCATENATE(DataSheet!L58," ",DataSheet!P58) -> 5 MΩ | M75: =CONCATENATE(TEXT(DataSheet!AH58,"0.000")," ",DataSheet!P58) -> #DIV/0! | Q75: =CONCATENATE(TEXT(DataSheet!AM58,"0.000")," ",DataSheet!P58) -> #DIV/0! | U75: =CONCATENATE(TEXT(DataSheet!EL58,"0.000 0")," ",DataSheet!EH58) -> #DIV/0!
E76: =DataSheet!F59 -> 40 MΩ | I76: =CONCATENATE(DataSheet!L59," ",DataSheet!P59) -> 10 MΩ | M76: =CONCATENATE(TEXT(DataSheet!AH59,"0.00")," ",DataSheet!P59) -> #DIV/0! | Q76: =CONCATENATE(TEXT(DataSheet!AM59,"0.00")," ",DataSheet!P59) -> #DIV/0! | U76: =CONCATENATE(TEXT(DataSheet!EL59,"0.000 0")," ",DataSheet!EH59) -> #DIV/0!
...

Sheet DataSheet
B3: CALIBRATION DATASHEET
F5: Work Order No.: | AI5: Technical ID:
B6: Unit Under Calibration
B7: Description | J7: : | K7: Digital Multimeter | AB7: Received Date | AK7: :
B9: Manufacturer | J9: : | K9: Fluke | AB9: Calibration Date | AK9: :
B11: Model | J11: : | K11: 117 | AB11: Options Installed | AK11: : | AL11: none
B13: Serial Number | J13: : | AB13: Customer P.O. | AK13: : | AL13: none
B15: Range | J15: : | K15: See specification sheet | AB15: Asset Number | AK15: : | AL15: none
B17: Res/Readability | J17: : | K17: See specification sheet | AB17: Accuracy | AK17: : | AL17: See specification sheet
B19: Prev. SES Cal Cert: | J19: : | K19: none | AB19: Previous Technician | AK19: : | AL19: none
B22: Customer Details | AB22: Calibration Location
B23: Company | G23: : | AE23: X | AG23: In-House (SONJU Laboratory)
B25: Address | G25: : | AG25: On-Site Calibration (Please Specify)
AG27: Electrical Calibration Area
B29: Reference Standard/s Used
B30: Description | Q30: Serial No. | AB30: Cal Report Ref. | AO30: Due Date
B31: Multiproduct Calibrator | Q31: 8100021 | AB31: 24-9973-01ALT Rev.00
B33: Accessory Used
B34: Description | Q34: Serial No. | AB34: Brand | AO34: Model
B35: none | Q35: none | AB35: none | AO35: none
B37: Environmental Condition | AB37: Calibration Method
F38: Temperature | O38: Relative Humidity | AB38: As per Manufacturer's recommended performance tests procedure for Fluke 117 Digital Multimeters Calibration Information, 1st - rev., September 2006.
H39: Start: | K39: oC | Q39: Start: | T39: %rh
H40: End: | K40: oC | Q40: End: | T40: %rh
B42: Observations
AU43: Adjustment
AU44: Needed?
AX45: YES
AW46: x | AX46: NO
B48: Measurement Results
F50: Resistance Test | BY50: Standard | CL50: Drift | CY50: Resolution | DM50: Repeatability | EB50: Expanded Uncertainty | EJ50: MINIMUM CMC | EL50: FINAL UNCERTAINTY DECLARATION
F51: Range | L51: Nominal Value | S51: Measured Value | AH51: Average | AM51: Error | BC51: Tolerance | BH51: Upper Limit | BM51: Lower Limit | BR51: Remarks | BY51: Source | BZ51: Distribution | CA51: Type | CB51: or | CC51: Unit | CD51: Divisor | CE51: Ui | CF51: Ci | CG51: UiCi | CH51: (UiCi)^2 | CI51: Vi | CJ51: (UiCi)^4 / Vi | CL51: Source | CM51: Distribution | CN51: Type | CO51: or | CP51: Unit | CQ51: Divisor | CR51: Ui | CS51: Ci | CT51: UiCi | CU51: (UiCi)^2 | CV51: Vi | CW51: (UiCi)^4 / Vi | CY51: Resolution | CZ51: Source | DA51: Distribution | DB51: Type | DC51: or | DD51: Unit | DE51: Divisor | DF51: Ui | DG51: Ci | DH51: UiCi | DI51: (UiCi)^2 | DJ51: Vi | DK51: (UiCi)^4 / Vi | DM51: No. of trial | DN51: Std. Dev | DO51: Source | DP51: Distribution | DQ51: Type | DR51: or | DS51: Unit | DT51: Divisor | DU51: Ui | DV51: Ci | DW51: UiCi | DX51: (UiCi)^2 | DY51: Vi | DZ51: (UiCi)^4 / Vi | EB51: Sum of | EC51: Sum of | ED51: COMBINED STANDARD | EE51: EFFECTIVE DEGREES | EF51: C. FACTOR, k = student's | EG51: EXPANDED UNCERTAINTY,
S52: 1 | X52: 2 | AC52: 3 | CB52: (±) | CO52: (±) | DC52: (±) | DR52: (±) | EB52: (UiCi)^2 | EC52: (UiCi)^4 | ED52: UNCERTAINTY, Uc | EE52: OF FREEDOM, Veff | EF52: t for Veff and 95 % C.L. | EG52: U @ 95 % C.L. ±
F53: 600 Ω | L53: 0 | P53: Ω | AH53: =AVERAGE(S53:AG53) -> #DIV/0! | AM53: =AH53-L53 -> #DIV/0! | BC53: =(AH53*0.9%)+(2+CY53) -> #DIV/0! | BH53: =L53+BC53 -> #DIV/0! | BM53: =L53-BC53 -> #DIV/0! | BR53: =IF(AND(AH53<=BH53,AH53>=BM53),"PASS","FAIL") -> #DIV/0! | BY53: COC | BZ53: Normal | CA53: B | CB53: 7.7e-05 | CC53: =P53 -> Ω | CD53: 2 | CE53: =CB53/CD53 -> 3.85e-05 | CF53: 1 | CG53: =CE53*CF53 -> 3.85e-05 | CH53: =CG53^2 -> 1.48225e-09 | CI53: 200 | CJ53: =CG53^4/CI53 -> 1.0985325e-20 | CL53: Annual Drift | CM53: Rectangular | CN53: B | CO53: 0 | CP53: =CC53 -> Ω | CQ53: =SQRT(3) -> 1.7320508 | CR53: =CO53/CQ53 -> 0 | CS53: 1 | CT53: =CR53*CS53 -> 0 | CU53: =CT53^2 -> 0 | CV53: 200 | CW53: =CT53^4/CV53 -> 0 | CY53: 0.1 | CZ53: Readability | DA53: Rectangular | DB53: B | DC53: =CY53/2 -> 0.05 | DD53: =P53 -> Ω | DE53: =SQRT(3) -> 1.7320508 | DF53: =DC53/DE53 -> 0.028867513 | DG53: 1 | DH53: =DF53*DG53 -> 0.028867513 | DI53: =DH53^2 -> 0.00083333333 | DJ53: 200 | DK53: =DH53^4/DJ53 -> 3.4722222e-09 | DM53: 3 | DN53: =STDEV(S53:AG53) -> #DIV/0! | DO53: Std. Dev of Reading | DP53: Normal | DQ53: A | DR53: =DN53 -> #DIV/0! | DS53: =P53 -> Ω | DT53: =SQRT(DM53) -> 1.7320508 | DU53: =DR53/DT53 -> #DIV/0! | DV53: 1 | DW53: =DU53*DV53 -> #DIV/0! | DX53: =DW53^2 -> #DIV/0! | DY53: 2 | DZ53: =DW53^4/DY53 -> #DIV/0! | EB53: =CH53+DI53+DX53 -> #DIV/0! | EC53: =CJ53+DK53+DZ53 -> #DIV/0! | ED53: =SQRT(EB53) -> #DIV/0! | EE53: =(ED53^4)/EC53 -> #DIV/0! | EF53: =ROUND(TINV(0.05,EE53),0) -> #DIV/0! | EG53: =(ED53*EF53) -> #DIV/0! | EH53: =P53 -> Ω | EJ53: 0.0078 | EK53: =EH53 -> Ω | EL53: =MAX(EJ53,EG53) -> #DIV/0! | EM53: =EK53 -> Ω
F54: 600 Ω | L54: 500 | P54: Ω | AH54: =AVERAGE(S54:AG54) -> #DIV/0! | AM54: =AH54-L54 -> #DIV/0! | BC54: =(AH54*0.9%)+(2+CY54) -> #DIV/0! | BH54: =L54+BC54 -> #DIV/0! | BM54: =L54-BC54 -> #DIV/0! | BR54: =IF(AND(AH54<=BH54,AH54>=BM54),"PASS","FAIL") -> #DIV/0! | BY54: COC | BZ54: Normal | CA54: B | CB54: 0.003 | CC54: =P54 -> Ω | CD54: 2 | CE54: =CB54/CD54 -> 0.0015 | CF54: 1 | CG54: =CE54*CF54 -> 0.0015 | CH54: =CG54^2 -> 2.25e-06 | CI54: 200 | CJ54: =CG54^4/CI54 -> 2.53125e-14 | CL54: Annual Drift | CM54: Rectangular | CN54: B | CO54: 0 | CP54: =CC54 -> Ω | CQ54: =SQRT(3) -> 1.7320508 | CR54: =CO54/CQ54 -> 0 | CS54: 1 | CT54: =CR54*CS54 -> 0 | CU54: =CT54^2 -> 0 | CV54: 200 | CW54: =CT54^4/CV54 -> 0 | CY54: 0.1 | CZ54: Readability | DA54: Rectangular | DB54: B | DC54: =CY54/2 -> 0.05 | DD54: =P54 -> Ω | DE54: =SQRT(3) -> 1.7320508 | DF54: =DC54/DE54 -> 0.028867513 | DG54: 1 | DH54: =DF54*DG54 -> 0.028867513 | DI54: =DH54^2 -> 0.00083333333 | DJ54: 200 | DK54: =DH54^4/DJ54 -> 3.4722222e-09 | DM54: 3 | DN54: =STDEV(S54:AG54) -> #DIV/0! | DO54: Std. Dev of Reading | DP54: Normal | DQ54: A | DR54: =DN54 -> #DIV/0! | DS54: =P54 -> Ω | DT54: =SQRT(DM54) -> 1.7320508 | DU54: =DR54/DT54 -> #DIV/0! | DV54: 1 | DW54: =DU54*DV54 -> #DIV/0! | DX54: =DW54^2 -> #DIV/0! | DY54: 2 | DZ54: =DW54^4/DY54 -> #DIV/0! | EB54: =CH54+DI54+DX54 -> #DIV/0! | EC54: =CJ54+DK54+DZ54 -> #DIV/0! | ED54: =SQRT(EB54) -> #DIV/0! | EE54: =(ED54^4)/EC54 -> #DIV/0! | EF54: =ROUND(TINV(0.05,EE54),0) -> #DIV/0! | EG54: =(ED54*EF54) -> #DIV/0! | EH54: =P54 -> Ω | EJ54: 0.023 | EK54: =EH54 -> Ω | EL54: =MAX(EJ54,EG54) -> #DIV/0! | EM54: =EK54 -> Ω
F55: 6 kΩ | L55: 5 | P55: kΩ | AH55: =AVERAGE(S55:AG55) -> #DIV/0! | AM55: =AH55-L55 -> #DIV/0! | BC55: =(AH55*0.9%)+(1+CY55) -> #DIV/0! | BH55: =L55+BC55 -> #DIV/0! | BM55: =L55-BC55 -> #DIV/0! | BR55: =IF(AND(AH55<=BH55,AH55>=BM55),"PASS","FAIL") -> #DIV/0! | BY55: COC | BZ55: Normal | CA55: B | CB55: 5.5e-05 | CC55: =P55 -> kΩ | CD55: 2 | CE55: =CB55/CD55 -> 2.75e-05 | CF55: 1 | CG55: =CE55*CF55 -> 2.75e-05 | CH55: =CG55^2 -> 7.5625e-10 | CI55: 200 | CJ55: =CG55^4/CI55 -> 2.8595703e-21 | CL55: Annual Drift | CM55: Rectangular | CN55: B | CO55: 0 | CP55: =CC55 -> kΩ | CQ55: =SQRT(3) -> 1.7320508 | CR55: =CO55/CQ55 -> 0 | CS55: 1 | CT55: =CR55*CS55 -> 0 | CU55: =CT55^2 -> 0 | CV55: 200 | CW55: =CT55^4/CV55 -> 0 | CY55: 0.001 | CZ55: Readability | DA55: Rectangular | DB55: B | DC55: =CY55/2 -> 0.0005 | DD55: =P55 -> kΩ | DE55: =SQRT(3) -> 1.7320508 | DF55: =DC55/DE55 -> 0.00028867513 | DG55: 1 | DH55: =DF55*DG55 -> 0.00028867513 | DI55: =DH55^2 -> 8.3333333e-08 | DJ55: 200 | DK55: =DH55^4/DJ55 -> 3.4722222e-17 | DM55: 3 | DN55: =STDEV(S55:AG55) -> #DIV/0! | DO55: Std. Dev of Reading | DP55: Normal | DQ55: A | DR55: =DN55 -> #DIV/0! | DS55: =P55 -> kΩ | DT55: =SQRT(DM55) -> 1.7320508 | DU55: =DR55/DT55 -> #DIV/0! | DV55: 1 | DW55: =DU55*DV55 -> #DIV/0! | DX55: =DW55^2 -> #DIV/0! | DY55: 2 | DZ55: =DW55^4/DY55 -> #DIV/0! | EB55: =CH55+DI55+DX55 -> #DIV/0! | EC55: =CJ55+DK55+DZ55 -> #DIV/0! | ED55: =SQRT(EB55) -> #DIV/0! | EE55: =(ED55^4)/EC55 -> #DIV/0! | EF55: =ROUND(TINV(0.05,EE55),0) -> #DIV/0! | EG55: =(ED55*EF55) -> #DIV/0! | EH55: =P55 -> kΩ | EJ55: 0.00023 | EK55: =EH55 -> kΩ | EL55: =MAX(EJ55,EG55) -> #DIV/0! | EM55: =EK55 -> kΩ
F56: 60 kΩ | L56: 50 | P56: kΩ | AH56: =AVERAGE(S56:AG56) -> #DIV/0! | AM56: =AH56-L56 -> #DIV/0! | BC56: =(AH56*0.9%)+(1+CY56) -> #DIV/0! | BH56: =L56+BC56 -> #DIV/0! | BM56: =L56-BC56 -> #DIV/0! | BR56: =IF(AND(AH56<=BH56,AH56>=BM56),"PASS","FAIL") -> #DIV/0! | BY56: COC | BZ56: Normal | CA56: B | CB56: 0.00081 | CC56: =P56 -> kΩ | CD56: 2 | CE56: =CB56/CD56 -> 0.000405 | CF56: 1 | CG56: =CE56*CF56 -> 0.000405 | CH56: =CG56^2 -> 1.64025e-07 | CI56: 200 | CJ56: =CG56^4/CI56 -> 1.34521e-16 | CL56: Annual Drift | CM56: Rectangular | CN56: B | CO56: 0 | CP56: =CC56 -> kΩ | CQ56: =SQRT(3) -> 1.7320508 | CR56: =CO56/CQ56 -> 0 | CS56: 1 | CT56: =CR56*CS56 -> 0 | CU56: =CT56^2 -> 0 | CV56: 200 | CW56: =CT56^4/CV56 -> 0 | CY56: 0.01 | CZ56: Readability | DA56: Rectangular | DB56: B | DC56: =CY56/2 -> 0.005 | DD56: =P56 -> kΩ | DE56: =SQRT(3) -> 1.7320508 | DF56: =DC56/DE56 -> 0.0028867513 | DG56: 1 | DH56: =DF56*DG56 -> 0.0028867513 | DI56: =DH56^2 -> 8.3333333e-06 | DJ56: 200 | DK56: =DH56^4/DJ56 -> 3.4722222e-13 | DM56: 3 | DN56: =STDEV(S56:AG56) -> #DIV/0! | DO56: Std. Dev of Reading | DP56: Normal | DQ56: A | DR56: =DN56 -> #DIV/0! | DS56: =P56 -> kΩ | DT56: =SQRT(DM56) -> 1.7320508 | DU56: =DR56/DT56 -> #DIV/0! | DV56: 1 | DW56: =DU56*DV56 -> #DIV/0! | DX56: =DW56^2 -> #DIV/0! | DY56: 2 | DZ56: =DW56^4/DY56 -> #DIV/0! | EB56: =CH56+DI56+DX56 -> #DIV/0! | EC56: =CJ56+DK56+DZ56 -> #DIV/0! | ED56: =SQRT(EB56) -> #DIV/0! | EE56: =(ED56^4)/EC56 -> #DIV/0! | EF56: =ROUND(TINV(0.05,EE56),0) -> #DIV/0! | EG56: =(ED56*EF56) -> #DIV/0! | EH56: =P56 -> kΩ | EJ56: 0.0015 | EK56: =EH56 -> kΩ | EL56: =MAX(EJ56,EG56) -> #DIV/0! | EM56: =EK56 -> kΩ
F57: 600 kΩ | L57: 500 | P57: kΩ | AH57: =AVERAGE(S57:AG57) -> #DIV/0! | AM57: =AH57-L57 -> #DIV/0! | BC57: =(AH57*0.9%)+(1+CY57) -> #DIV/0! | BH57: =L57+BC57 -> #DIV/0! | BM57: =L57-BC57 -> #DIV/0! | BR57: =IF(AND(AH57<=BH57,AH57>=BM57),"PASS","FAIL") -> #DIV/0! | BY57: COC | BZ57: Normal | CA57: B | CB57: 0.0066 | CC57: =P57 -> kΩ | CD57: 2 | CE57: =CB57/CD57 -> 0.0033 | CF57: 1 | CG57: =CE57*CF57 -> 0.0033 | CH57: =CG57^2 -> 1.089e-05 | CI57: 200 | CJ57: =CG57^4/CI57 -> 5.929605e-13 | CL57: Annual Drift | CM57: Rectangular | CN57: B | CO57: 0 | CP57: =CC57 -> kΩ | CQ57: =SQRT(3) -> 1.7320508 | CR57: =CO57/CQ57 -> 0 | CS57: 1 | CT57: =CR57*CS57 -> 0 | CU57: =CT57^2 -> 0 | CV57: 200 | CW57: =CT57^4/CV57 -> 0 | CY57: 0.1 | CZ57: Readability | DA57: Rectangular | DB57: B | DC57: =CY57/2 -> 0.05 | DD57: =P57 -> kΩ | DE57: =SQRT(3) -> 1.7320508 | DF57: =DC57/DE57 -> 0.028867513 | DG57: 1 | DH57: =DF57*DG57 -> 0.028867513 | DI57: =DH57^2 -> 0.00083333333 | DJ57: 200 | DK57: =DH57^4/DJ57 -> 3.4722222e-09 | DM57: 3 | DN57: =STDEV(S57:AG57) -> #DIV/0! | DO57: Std. Dev of Reading | DP57: Normal | DQ57: A | DR57: =DN57 -> #DIV/0! | DS57: =P57 -> kΩ | DT57: =SQRT(DM57) -> 1.7320508 | DU57: =DR57/DT57 -> #DIV/0! | DV57: 1 | DW57: =DU57*DV57 -> #DIV/0! | DX57: =DW57^2 -> #DIV/0! | DY57: 2 | DZ57: =DW57^4/DY57 -> #DIV/0! | EB57: =CH57+DI57+DX57 -> #DIV/0! | EC57: =CJ57+DK57+DZ57 -> #DIV/0! | ED57: =SQRT(EB57) -> #DIV/0! | EE57: =(ED57^4)/EC57 -> #DIV/0! | EF57: =ROUND(TINV(0.05,EE57),0) -> #DIV/0! | EG57: =(ED57*EF57) -> #DIV/0! | EH57: =P57 -> kΩ | EJ57: 0.016 | EK57: =EH57 -> kΩ | EL57: =MAX(EJ57,EG57) -> #DIV/0! | EM57: =EK57 -> kΩ
F58: 6 MΩ | L58: 5 | P58: MΩ | AH58: =AVERAGE(S58:AG58) -> #DIV/0! | AM58: =AH58-L58 -> #DIV/0! | BC58: =(AH58*0.9%)+(1+CY58) -> #DIV/0! | BH58: =L58+BC58 -> #DIV/0! | BM58: =L58-BC58 -> #DIV/0! | BR58: =IF(AND(AH58<=BH58,AH58>=BM58),"PASS","FAIL") -> #DIV/0! | BY58: COC | BZ58: Normal | CA58: B | CB58: 0.00048 | CC58: =P58 -> MΩ | CD58: 2 | CE58: =CB58/CD58 -> 0.00024 | CF58: 1 | CG58: =CE58*CF58 -> 0.00024 | CH58: =CG58^2 -> 5.76e-08 | CI58: 200 | CJ58: =CG58^4/CI58 -> 1.65888e-17 | CL58: Annual Drift | CM58: Rectangular | CN58: B | CO58: 0 | CP58: =CC58 -> MΩ | CQ58: =SQRT(3) -> 1.7320508 | CR58: =CO58/CQ58 -> 0 | CS58: 1 | CT58: =CR58*CS58 -> 0 | CU58: =CT58^2 -> 0 | CV58: 200 | CW58: =CT58^4/CV58 -> 0 | CY58: 0.001 | CZ58: Readability | DA58: Rectangular | DB58: B | DC58: =CY58/2 -> 0.0005 | DD58: =P58 -> MΩ | DE58: =SQRT(3) -> 1.7320508 | DF58: =DC58/DE58 -> 0.00028867513 | DG58: 1 | DH58: =DF58*DG58 -> 0.00028867513 | DI58: =DH58^2 -> 8.3333333e-08 | DJ58: 200 | DK58: =DH58^4/DJ58 -> 3.4722222e-17 | DM58: 3 | DN58: =STDEV(S58:AG58) -> #DIV/0! | DO58: Std. Dev of Reading | DP58: Normal | DQ58: A | DR58: =DN58 -> #DIV/0! | DS58: =P58 -> MΩ | DT58: =SQRT(DM58) -> 1.7320508 | DU58: =DR58/DT58 -> #DIV/0! | DV58: 1 | DW58: =DU58*DV58 -> #DIV/0! | DX58: =DW58^2 -> #DIV/0! | DY58: 2 | DZ58: =DW58^4/DY58 -> #DIV/0! | EB58: =CH58+DI58+DX58 -> #DIV/0! | EC58: =CJ58+DK58+DZ58 -> #DIV/0! | ED58: =SQRT(EB58) -> #DIV/0! | EE58: =(ED58^4)/EC58 -> #DIV/0! | EF58: =ROUND(TINV(0.05,EE58),0) -> #DIV/0! | EG58: =(ED58*EF58) -> #DIV/0! | EH58: =P58 -> MΩ | EJ58: 0.00053 | EK58: =EH58 -> MΩ | EL58: =MAX(EJ58,EG58) -> #DIV/0! | EM58: =EK58 -> MΩ
F59: 40 MΩ | L59: 10 | P59: MΩ | AH59: =AVERAGE(S59:AG59) -> #DIV/0! | AM59: =AH59-L59 -> #DIV/0! | BC59: =(AH59*5%)+(2+CY59) -> #DIV/0! | BH59: =L59+BC59 -> #DIV/0! | BM59: =L59-BC59 -> #DIV/0! | BR59: =IF(AND(AH59<=BH59,AH59>=BM59),"PASS","FAIL") -> #DIV/0! | BY59: COC | BZ59: Normal | CA59: B | CB59: 0.00048 | CC59: =P59 -> MΩ | CD59: 2 | CE59: =CB59/CD59 -> 0.00024 | CF59: 1 | CG59: =CE59*CF59 -> 0.00024 | CH59: =CG59^2 -> 5.76e-08 | CI59: 200 | CJ59: =CG59^4/CI59 -> 1.65888e-17 | CL59: Annual Drift | CM59: Rectangular | CN59: B | CO59: 0 | CP59: =CC59 -> MΩ | CQ59: =SQRT(3) -> 1.7320508 | CR59: =CO59/CQ59 -> 0 | CS59: 1 | CT59: =CR59*CS59 -> 0 | CU59: =CT59^2 -> 0 | CV59: 200 | CW59: =CT59^4/CV59 -> 0 | CY59: 0.01 | CZ59: Readability | DA59: Rectangular | DB59: B | DC59: =CY59/2 -> 0.005 | DD59: =P59 -> MΩ | DE59: =SQRT(3) -> 1.7320508 | DF59: =DC59/DE59 -> 0.0028867513 | DG59: 1 | DH59: =DF59*DG59 -> 0.0028867513 | DI59: =DH59^2 -> 8.3333333e-06 | DJ59: 200 | DK59: =DH59^4/DJ59 -> 3.4722222e-13 | DM59: 3 | DN59: =STDEV(S59:AG59) -> #DIV/0! | DO59: Std. Dev of Reading | DP59: Normal | DQ59: A | DR59: =DN59 -> #DIV/0! | DS59: =P59 -> MΩ | DT59: =SQRT(DM59) -> 1.7320508 | DU59: =DR59/DT59 -> #DIV/0! | DV59: 1 | DW59: =DU59*DV59 -> #DIV/0! | DX59: =DW59^2 -> #DIV/0! | DY59: 2 | DZ59: =DW59^4/DY59 -> #DIV/0! | EB59: =CH59+DI59+DX59 -> #DIV/0! | EC59: =CJ59+DK59+DZ59 -> #DIV/0! | ED59: =SQRT(EB59) -> #DIV/0! | EE59: =(ED59^4)/EC59 -> #DIV/0! | EF59: =ROUND(TINV(0.05,EE59),0) -> #DIV/0! | EG59: =(ED59*EF59) -> #DIV/0! | EH59: =P59 -> MΩ | EJ59: 0.00053 | EK59: =EH59 -> MΩ | EL59: =MAX(EJ59,EG59) -> #DIV/0! | EM59: =EK59 -> MΩ
...

Sheet Specification
A1: https://www.instrumart.com/assets/fluke115_116_117_manual.pdf
