Workbook
Name DRY: #REF!
Name DRY: #REF!
Name dryx: #REF!
Name WET: #REF!
Name WET: #REF!
Name WET: #REF!

Sheet Cal Certificate
C5: Calibration Certificate
R7: Certificate No.: | V7: =CONCATENATE("25-",DataSheet!L7,DataSheet!N7,DataSheet!O7,DataSheet!AN7," ","Rev.00") -> 25-5465-09DBN Rev.00
C9: Customer : | O9: Location of Calibration :
D10: =DataSheet!H25 -> Company 1 | P10: =IF(DataSheet!AE25="x","SONJU ENGINEERING SERVICES",D10) -> Company 1
D11: =DataSheet!H27 -> comp1 add | P11: =IF(DataSheet!AE25="x",DataSheet!AG29,DataSheet!AG29) -> comp1 add
C15: Manufacturer: | H15: =DataSheet!K11 -> AA | O15: Description: | T15: =DataSheet!K9 -> AA
C16: Model No: | H16: =DataSheet!K13 -> AA | O16: Options Installed: | T16: =DataSheet!AL13 -> 5435354
C17: Serial No: | H17: =DataSheet!K15 -> 5435354 | O17: Customer Asset No: | T17: =DataSheet!AL17 -> 5435354
C18: Calibration Date: | H18: =DataSheet!AL11 -> 45756 | O18: Work Order No.: | T18: =DataSheet!L7 -> 5465-09
C19: Received Date: | H19: =DataSheet!AL9 -> 45756 | O19: Customer P.O.: | T19: =DataSheet!AL15 -> 5435354
C20: Temperature: | H20: =IF(DataSheet!AE25="x","23 °C ± 5 °C",CONCATENATE(ROUND(AVERAGE(DataSheet!K41:L42),1)," ","°C")) -> 5.5 °C | O20: Humidity: | T20: =IF(DataSheet!AE25="x","55 %rh ± 15 %rh",CONCATENATE(ROUND(AVERAGE(DataSheet!T41:U42),1)," ","%rh")) -> 7 %rh
C23: Cal Method / Procedure :
C24: =DataSheet!AB40 -> As per SONJU Engineering Services Work Instruction 7W-02-54 Digital Multimeter Calibration Procedure.
C26: This is to certify that the above Measuring and Test Equipment has been calibrated by SONJU Engineering Services in accordance with relevant calibration procedure defined for this instrument.
C29: Uncertainty:
C30: The expanded uncertainty of measurement for the results given in this certificate was estimated with a coverage factor of k = 2 at 95% level of confidence. The uncertainties of measurement were calculated using a budget worksheet based on JCGM 100:2008 Evaluation of measurement data - Guide to the Expression of Uncertainty in Measurement, 1st edition- 2008.
C34: Traceability:
C35: The instrument was calibrated using reference standard/s traceable to SI Units as maintained by NML-ITDI (Philippines) through SONJU Engineering Services (Philippines)
C38: Reference Standard Used:
D40: Description | J40: Serial No. | P40: Cal Report Ref. | V40: Due Date
D42: =DataSheet!B33 -> dfsf | J42: =DataSheet!Q33 -> sfdfsf | P42: =DataSheet!AB33 -> fsfsfss | V42: =DataSheet!AO33 -> Tuesday, 2 September 2025
C44: Remarks:
C45: 1. The results were the average of the three (3) readings and were obtained during the time of calibration and refer only to the particular instrument submitted. Should the instrument be modified or damaged in any way, or develop inconsistent readings, the results may not be valid and the unit will require recalibration.
C48: 2. The user should determine the suitability of this instrument for its intended use.
C49: 3. Preliminary Inspection: No response at high and low current.
C50: 4. A positve error is to subtracted to the UUT indication and negative error added to give true value.
C51: 5. As per customer request the next calibration due date is on: | O51: =EDATE(DataSheet!AL11,12) -> 46121
E54: =DataSheet!B140 -> Darwin F. Aliado | S54: =DataSheet!B143 -> Jennefer S. Ilas
E55: Calibration Officer | S55: Approved Signatory
D57: Issue Date :
C65: Measurement Results:
E67: =DataSheet!F52 -> DC Voltage Test
E68: Range | I68: Nominal Value | M68: Measured Value | Q68: Error | U68: Uncertainty
E70: =DataSheet!F55 -> 600 mV | I70: =CONCATENATE(DataSheet!L55," ",DataSheet!P55) -> 60 mV | M70: =CONCATENATE(TEXT(DataSheet!AM55,"0.0")," ",DataSheet!P55) -> 60.0 mV | Q70: =CONCATENATE(TEXT(DataSheet!AR55,"0.0")," ",DataSheet!P55) -> 0.0 mV | U70: =CONCATENATE(," ",TEXT(DataSheet!DD55,"0.000")," ",DataSheet!CZ55) -> 0.058 mV
I71: =CONCATENATE(DataSheet!L56," ",DataSheet!P56) -> 540 mV | M71: =CONCATENATE(TEXT(DataSheet!AM56,"0.0")," ",DataSheet!P56) -> 540.0 mV | Q71: =CONCATENATE(TEXT(DataSheet!AR56,"0.0")," ",DataSheet!P56) -> 0.0 mV | U71: =CONCATENATE(," ",TEXT(DataSheet!DD56,"0.000")," ",DataSheet!CZ56) -> 0.058 mV
I72: =CONCATENATE(DataSheet!L57," ",DataSheet!P57) -> -540 mV | M72: =CONCATENATE(TEXT(DataSheet!AM57,"0.0")," ",DataSheet!P57) -> -540.0 mV | Q72: =CONCATENATE(TEXT(DataSheet!AR57,"0.0")," ",DataSheet!P57) -> 0.0 mV | U72: =CONCATENATE(," ",TEXT(DataSheet!DD57,"0.000")," ",DataSheet!CZ57) -> 0.058 mV
E73: =DataSheet!F58 -> 6 V | I73: =CONCATENATE(DataSheet!L58," ",DataSheet!P58) -> 0.6 V | M73: =CONCATENATE(TEXT(DataSheet!AM58,"0.000")," ",DataSheet!P58) -> 0.600 V | Q73: =CONCATENATE(TEXT(DataSheet!AR58,"0.000")," ",DataSheet!P58) -> 0.000 V | U73: =CONCATENATE(" ",TEXT(DataSheet!DD58,"0.000 00")," ",DataSheet!CZ58) -> 0.000 58 V
I74: =CONCATENATE(DataSheet!L59," ",DataSheet!P59) -> 5.4 V | M74: =CONCATENATE(TEXT(DataSheet!AM59,"0.000")," ",DataSheet!P59) -> 5.400 V | Q74: =CONCATENATE(TEXT(DataSheet!AR59,"0.000")," ",DataSheet!P59) -> 0.000 V | U74: =CONCATENATE(" ",TEXT(DataSheet!DD59,"0.000 00")," ",DataSheet!CZ59) -> 0.000 58 V
I75: =CONCATENATE(DataSheet!L60," ",DataSheet!P60) -> -5.4 V | M75: =CONCATENATE(TEXT(DataSheet!AM60,"0.000")," ",DataSheet!P60) -> -5.400 V | Q75: =CONCATENATE(TEXT(DataSheet!AR60,"0.000")," ",DataSheet!P60) -> 0.000 V | U75: =CONCATENATE(" ",TEXT(DataSheet!DD60,"0.000 00")," ",DataSheet!CZ60) -> 0.000 58 V
E76: =DataSheet!F61 -> 60 V | I76: =CONCATENATE(DataSheet!L61," ",DataSheet!P61) -> 6 V | M76: =CONCATENATE(TEXT(DataSheet!AM61,"0.00")," ",DataSheet!P61) -> 6.00 V | Q76: =CONCATENATE(TEXT(DataSheet!AR61,"0.00")," ",DataSheet!P61) -> 0.00 V | U76: =CONCATENATE(" ",TEXT(DataSheet!DD61,"0.000 0")," ",DataSheet!CZ61) -> 0.005 8 V
...

Sheet DataSheet
B5: CALIBRATION DATASHEET
F7: Work Order No.: | L7: 5465-09 | AI7: Technical ID: | AN7: DBN
B8: Unit Under Calibration
B9: Description | J9: : | K9: AA | AB9: Received Date | AK9: : | AL9: 45756
B11: Manufacturer | J11: : | K11: AA | AB11: Calibration Date | AK11: : | AL11: 45756
B13: Model | J13: : | K13: AA | AB13: Options Installed | AK13: : | AL13: 5435354
B15: Serial Number | J15: : | K15: 5435354 | AB15: Customer P.O. | AK15: : | AL15: 5435354
B17: Range | J17: : | K17: See Specification Sheet | AB17: Asset Number | AK17: : | AL17: 5435354
B19: Res/Readability | J19: : | K19: See Specification Sheet | AB19: Accuracy | AK19: : | AL19: See Specification Sheet
B21: Prev. SES Cal Cert: | J21: : | K21: NA | AB21: Previous Technician | AK21: : | AL21: NA
B24: Customer Details | AB24: Calibration Location
B25: Company | G25: : | H25: Company 1 | AG25: In-House (SONJU Laboratory)
B27: Address | G27: : | H27: comp1 add | AE27: x | AG27: On-Site Calibration (Please Specify)
AG29: comp1 add
B31: Reference Standard/s Used
B32: Description | Q32: Serial No. | AB32: Cal Report Ref. | AO32: Due Date
B33: dfsf | Q33: sfdfsf | AB33: fsfsfss | AO33: Tuesday, 2 September 2025
B34: fdgdgd | Q34: dgdgfdg | AB34: gdgdfg | AO34: Thursday, 18 September 2025
B35: Accessory Used
B36: Description | Q36: Serial No. | AB36: Brand | AO36: Model
B37: dgdfgdg | Q37: gdgfg | AB37: gdgfdg | AO37: gdfggdg
B38: dgfdgdf | Q38: dgdfgdg | AB38: dgfdgd | AO38: dgdfg
B39: Environmental Condition | AB39: Calibration Method
I40: Temperature | Q40: Relative Humidity | AB40: As per SONJU Engineering Services Work Instruction 7W-02-54 Digital Multimeter Calibration Procedure.
J41: Start: | K41: 1 | M41: oC | S41: Start: | T41: 2 | V41: %rh
J42: End: | K42: 10 | M42: oC | S42: End: | T42: 12 | V42: %rh
B44: Observations
C45: - | AU45: Adjustment
C46: - | AU46: Needed?
C47: - | AX47: YES
C48: - | AX48: NO
B50: Measurement Results
F52: DC Voltage Test | BB52: Based on Tolerance | BX52: Standard | CD52: Standard | CJ52: Unit Under Test | CP52: Unit Under Test | CV52: Expanded Uncertainty | DB52: MINIMUM CMC | DD52: FINAL UNCERTAINTY DECLARATION
F53: Range | L53: Nominal Value | S53: Frequency | X53: Measured Value | AM53: Average | AR53: Error | BB53: Tolerance | BG53: Upper Limit | BL53: Lower Limit | BQ53: Remarks | BX53: Source | BY53: Uncertainty | BZ53: Unit | CA53: Divisor | CB53: Ui | CD53: Source | CE53: Uncertainty | CF53: Unit | CG53: Divisor | CH53: Ui | CJ53: Source | CK53: Uncertainty | CL53: Unit | CM53: Divisor | CN53: Ui | CP53: Source | CQ53: Uncertainty | CR53: Unit | CS53: Divisor | CT53: Ui | CV53: COMBINED STANDARD | CW53: EFFECTIVE DEGREES | CX53: C. FACTOR, k = student's | CY53: EXPANDED UNCERTAINTY,
X54: 1 | AC54: 2 | AH54: 3 | CV54: UNCERTAINTY, Uc | CW54: OF FREEDOM, Veff | CX54: t for Veff and 95 % C.L. | CY54: U @ 95 % C.L. ±
F55: 600 mV | L55: 60 | P55: mV | X55: 60 | AC55: 60 | AH55: 60 | AM55: =AVERAGE(X55:AL55) -> 60 | AR55: =AM55-L55 -> 0 | BB55: =ABS(AM55*0.1%)+(1*CK55) -> 0.16 | BG55: =L55+BB55 -> 60.16 | BL55: =L55-BB55 -> 59.84 | BQ55: =IF(AND(AM55<=BG55,AM55>=BL55),"PASS","FAIL") -> PASS | BX55: CoC | BY55: 0.00077 | BZ55: =P55 -> mV | CA55: 2 | CB55: =BY55/CA55 -> 0.000385 | CD55: Annual Drift | CE55: 0 | CF55: =BZ55 -> mV | CG55: =SQRT(3) -> 1.7320508 | CH55: =CE55/CG55 -> 0 | CJ55: Readability | CK55: 0.1 | CL55: =P55 -> mV | CM55: =SQRT(12) -> 3.4641016 | CN55: =CK55/CM55 -> 0.028867513 | CP55: Repeatability | CQ55: =STDEV(X55:AL55) -> 0 | CR55: =P55 -> mV | CS55: =SQRT(3) -> 1.7320508 | CT55: =CQ55/CS55 -> 0 | CV55: =SQRT(SUMSQ(CT55,CN55,CH55,CB55)) -> 0.028870081 | CW55: =(CV55^4)/(((CT55^4)/2)+((CN55^4)/200)+((CH55^4)/200)+((CB55^4)/200)) -> 200.07115 | CX55: =ROUND(TINV(0.05,CW55),0) -> 2 | CY55: =(CV55*CX55) -> 0.057740161 | CZ55: =P55 -> mV | DB55: 0.0016 | DC55: =CZ55 -> mV | DD55: =MAX(DB55,CY55) -> 0.057740161 | DE55: unit
L56: =600*90% -> 540 | P56: mV | S56: - | X56: 540 | AC56: 540 | AH56: 540 | AM56: =AVERAGE(X56:AL56) -> 540 | AR56: =AM56-L56 -> 0 | BB56: =ABS(AM56*0.1%)+(1*CK56) -> 0.64 | BG56: =L56+BB56 -> 540.64 | BL56: =L56-BB56 -> 539.36 | BQ56: =IF(AND(AM56<=BG56,AM56>=BL56),"PASS","FAIL") -> PASS | BX56: CoC | BY56: 0.0021 | BZ56: =P56 -> mV | CA56: 2 | CB56: =BY56/CA56 -> 0.00105 | CD56: Annual Drift | CE56: 0 | CF56: =BZ56 -> mV | CG56: =SQRT(3) -> 1.7320508 | CH56: =CE56/CG56 -> 0 | CJ56: Readability | CK56: 0.1 | CL56: =P56 -> mV | CM56: =SQRT(12) -> 3.4641016 | CN56: =CK56/CM56 -> 0.028867513 | CP56: Repeatability | CQ56: =STDEV(X56:AL56) -> 0 | CR56: =P56 -> mV | CS56: =SQRT(3) -> 1.7320508 | CT56: =CQ56/CS56 -> 0 | CV56: =SQRT(SUMSQ(CT56,CN56,CH56,CB56)) -> 0.028886603 | CW56: =(CV56^4)/(((CT56^4)/2)+((CN56^4)/200)+((CH56^4)/200)+((CB56^4)/200)) -> 200.5292 | CX56: =ROUND(TINV(0.05,CW56),0) -> 2 | CY56: =(CV56*CX56) -> 0.057773206 | CZ56: =P56 -> mV | DB56: 0.0018 | DC56: =CZ56 -> mV | DD56: =MAX(DB56,CY56) -> 0.057773206 | DE56: =DC56 -> mV
L57: =600*-90% -> -540 | P57: mV | S57: - | X57: -540 | AC57: -540 | AH57: -540 | AM57: =AVERAGE(X57:AL57) -> -540 | AR57: =AM57-L57 -> 0 | BB57: =ABS(AM57*0.1%)+(1*CK57) -> 0.64 | BG57: =L57+BB57 -> -539.36 | BL57: =L57-BB57 -> -540.64 | BQ57: =IF(AND(AM57<=BG57,AM57>=BL57),"PASS","FAIL") -> PASS | BX57: CoC | BY57: 0.0021 | BZ57: =P57 -> mV | CA57: 2 | CB57: =BY57/CA57 -> 0.00105 | CD57: Annual Drift | CE57: 0 | CF57: =BZ57 -> mV | CG57: =SQRT(3) -> 1.7320508 | CH57: =CE57/CG57 -> 0 | CJ57: Readability | CK57: 0.1 | CL57: =P57 -> mV | CM57: =SQRT(12) -> 3.4641016 | CN57: =CK57/CM57 -> 0.028867513 | CP57: Repeatability | CQ57: =STDEV(X57:AL57) -> 0 | CR57: =P57 -> mV | CS57: =SQRT(3) -> 1.7320508 | CT57: =CQ57/CS57 -> 0 | CV57: =SQRT(SUMSQ(CT57,CN57,CH57,CB57)) -> 0.028886603 | CW57: =(CV57^4)/(((CT57^4)/2)+((CN57^4)/200)+((CH57^4)/200)+((CB57^4)/200)) -> 200.5292 | CX57: =ROUND(TINV(0.05,CW57),0) -> 2 | CY57: =(CV57*CX57) -> 0.057773206 | CZ57: =P57 -> mV | DB57: 0.0018 | DC57: =CZ57 -> mV | DD57: =MAX(DB57,CY57) -> 0.057773206 | DE57: =DC57 -> mV
F58: 6 V | L58: =6*10% -> 0.6 | P58: V | S58: - | X58: 0.6 | AC58: 0.6 | AH58: 0.6 | AM58: =AVERAGE(X58:AL58) -> 0.6 | AR58: =AM58-L58 -> 0 | BB58: =ABS(AM58*0.1%)+(1*CK58) -> 0.0016 | BG58: =L58+BB58 -> 0.6016 | BL58: =L58-BB58 -> 0.5984 | BQ58: =IF(AND(AM58<=BG58,AM58>=BL58),"PASS","FAIL") -> PASS | BX58: CoC | BY58: 2.1e-06 | BZ58: =P58 -> V | CA58: 2 | CB58: =BY58/CA58 -> 1.05e-06 | CD58: Annual Drift | CE58: 0 | CF58: =BZ58 -> V | CG58: =SQRT(3) -> 1.7320508 | CH58: =CE58/CG58 -> 0 | CJ58: Readability | CK58: 0.001 | CL58: =P58 -> V | CM58: =SQRT(12) -> 3.4641016 | CN58: =CK58/CM58 -> 0.00028867513 | CP58: Repeatability | CQ58: =STDEV(X58:AL58) -> 0 | CR58: =P58 -> V | CS58: =SQRT(3) -> 1.7320508 | CT58: =CQ58/CS58 -> 0 | CV58: =SQRT(SUMSQ(CT58,CN58,CH58,CB58)) -> 0.00028867704 | CW58: =(CV58^4)/(((CT58^4)/2)+((CN58^4)/200)+((CH58^4)/200)+((CB58^4)/200)) -> 200.00529 | CX58: =ROUND(TINV(0.05,CW58),0) -> 2 | CY58: =(CV58*CX58) -> 0.00057735409 | CZ58: =P58 -> V | DB58: 1.8e-06 | DC58: =CZ58 -> V | DD58: =MAX(DB58,CY58) -> 0.00057735409 | DE58: =DC58 -> V
L59: =6*90% -> 5.4 | P59: V | S59: - | X59: 5.4 | AC59: 5.4 | AH59: 5.4 | AM59: =AVERAGE(X59:AL59) -> 5.4 | AR59: =AM59-L59 -> 0 | BB59: =ABS(AM59*0.1%)+(1*CK59) -> 0.0064 | BG59: =L59+BB59 -> 5.4064 | BL59: =L59-BB59 -> 5.3936 | BQ59: =IF(AND(AM59<=BG59,AM59>=BL59),"PASS","FAIL") -> PASS | BX59: CoC | BY59: 1.8e-05 | BZ59: =P59 -> V | CA59: 2 | CB59: =BY59/CA59 -> 9e-06 | CD59: Annual Drift | CE59: 0 | CF59: =BZ59 -> V | CG59: =SQRT(3) -> 1.7320508 | CH59: =CE59/CG59 -> 0 | CJ59: Readability | CK59: 0.001 | CL59: =P59 -> V | CM59: =SQRT(12) -> 3.4641016 | CN59: =CK59/CM59 -> 0.00028867513 | CP59: Repeatability | CQ59: =STDEV(X59:AL59) -> 1.087792e-15 | CR59: =P59 -> V | CS59: =SQRT(3) -> 1.7320508 | CT59: =CQ59/CS59 -> 6.2803698e-16 | CV59: =SQRT(SUMSQ(CT59,CN59,CH59,CB59)) -> 0.0002888154 | CW59: =(CV59^4)/(((CT59^4)/2)+((CN59^4)/200)+((CH59^4)/200)+((CB59^4)/200)) -> 200.3888 | CX59: =ROUND(TINV(0.05,CW59),0) -> 2 | CY59: =(CV59*CX59) -> 0.00057763079 | CZ59: =P59 -> V | DB59: 1e-05 | DC59: =CZ59 -> V | DD59: =MAX(DB59,CY59) -> 0.00057763079 | DE59: =DC59 -> V
...

Sheet PASSFAIL
B2: PASS/FAIL ANALYSIS
B3: Measurement Results | H3: Based on Tolerance | N3: Based on +/- Uncertainty Applied | X3: FINAL REMARKS
B5: =DataSheet!F52 -> DC Voltage Test
B7: Measured Value | D7: Tolerance | F7: Uncertainty | H7: Upper Limit | J7: Lower Limit | L7: Remarks | N7: Measured Value + Uncertainty | P7: Upper Limit | R7: Remarks | T7: Measured Value - Uncertainty | V7: Remarks
B10: =DataSheet!AM55 -> 60 | C10: =DataSheet!P55 -> mV | D10: =ABS((B10*0.7%)+(3*DataSheet!CK55)) -> 0.72 | E10: =C10 -> mV | F10: =DataSheet!DD55 -> 0.057740161 | G10: =E10 -> mV | H10: =DataSheet!L55+D10 -> 60.72 | I10: =G10 -> mV | J10: =DataSheet!L55-D10 -> 59.28 | K10: =I10 -> mV | L10: =IF(AND(B10<=H10,B10>=J10),"PASSED","FAILED") -> PASSED | N10: =F10+B10 -> 60.05774 | O10: =G10 -> mV | P10: =H10 -> 60.72 | Q10: =O10 -> mV | R10: =IF(AND(N10<=H10,N10>=J10),"PASSED","FAILED") -> PASSED | T10: =-F10+B10 -> 59.94226 | U10: =O10 -> mV | V10: =IF(AND(T10<=H10,T10>=J10),"PASSED","FAILED") -> PASSED | X10: =IF(AND(L10="PASSED",R10="PASSED",V10="PASSED"),"PASSED",IF(L10="FAILED","FAILED","UNDETERMINED")) -> PASSED
B11: =DataSheet!AM56 -> 540 | C11: =DataSheet!P56 -> mV | D11: =ABS((B11*0.7%)+(3*DataSheet!CK56)) -> 4.08 | E11: =C11 -> mV | F11: =DataSheet!DD56 -> 0.057773206 | G11: =E11 -> mV | H11: =DataSheet!L56+D11 -> 544.08 | I11: =G11 -> mV | J11: =DataSheet!L56-D11 -> 535.92 | K11: =I11 -> mV | L11: =IF(AND(B11<=H11,B11>=J11),"PASSED","FAILED") -> PASSED | N11: =F11+B11 -> 540.05777 | O11: =G11 -> mV | P11: =H11 -> 544.08 | Q11: =O11 -> mV | R11: =IF(AND(N11<=H11,N11>=J11),"PASSED","FAILED") -> PASSED | T11: =-F11+B11 -> 539.94223 | U11: =O11 -> mV | V11: =IF(AND(T11<=H11,T11>=J11),"PASSED","FAILED") -> PASSED | X11: =IF(AND(L11="PASSED",R11="PASSED",V11="PASSED"),"PASSED",IF(L11="FAILED","FAILED","UNDETERMINED")) -> PASSED
B12: =DataSheet!AM57 -> -540 | C12: =DataSheet!P57 -> mV | D12: =ABS((B12*0.7%)-(3*DataSheet!CK57)) -> 4.08 | E12: =C12 -> mV | F12: =DataSheet!DD57 -> 0.057773206 | G12: =E12 -> mV | H12: =DataSheet!L57+D12 -> -535.92 | I12: =G12 -> mV | J12: =DataSheet!L57-D12 -> -544.08 | K12: =I12 -> mV | L12: =IF(AND(B12<=H12,B12>=J12),"PASSED","FAILED") -> PASSED | N12: =F12+B12 -> -539.94223 | O12: =G12 -> mV | P12: =H12 -> -535.92 | Q12: =O12 -> mV | R12: =IF(AND(N12<=H12,N12>=J12),"PASSED","FAILED") -> PASSED | T12: =-F12+B12 -> -540.05777 | U12: =O12 -> mV | V12: =IF(AND(T12<=H12,T12>=J12),"PASSED","FAILED") -> PASSED | X12: =IF(AND(L12="PASSED",R12="PASSED",V12="PASSED"),"PASSED",IF(L12="FAILED","FAILED","UNDETERMINED")) -> PASSED
B13: =DataSheet!AM58 -> 0.6 | C13: =DataSheet!P58 -> V | D13: =ABS((B13*0.7%)+(3*DataSheet!CK58)) -> 0.0072 | E13: =C13 -> V | F13: =DataSheet!DD58 -> 0.00057735409 | G13: =E13 -> V | H13: =DataSheet!L58+D13 -> 0.6072 | I13: =G13 -> V | J13: =DataSheet!L58-D13 -> 0.5928 | K13: =I13 -> V | L13: =IF(AND(B13<=H13,B13>=J13),"PASSED","FAILED") -> PASSED | N13: =F13+B13 -> 0.60057735 | O13: =G13 -> V | P13: =H13 -> 0.6072 | Q13: =O13 -> V | R13: =IF(AND(N13<=H13,N13>=J13),"PASSED","FAILED") -> PASSED | T13: =-F13+B13 -> 0.59942265 | U13: =O13 -> V | V13: =IF(AND(T13<=H13,T13>=J13),"PASSED","FAILED") -> PASSED | X13: =IF(AND(L13="PASSED",R13="PASSED",V13="PASSED"),"PASSED",IF(L13="FAILED","FAILED","UNDETERMINED")) -> PASSED
B14: =DataSheet!AM59 -> 5.4 | C14: =DataSheet!P59 -> V | D14: =ABS((B14*0.7%)+(3*DataSheet!CK59)) -> 0.0408 | E14: =C14 -> V | F14: =DataSheet!DD59 -> 0.00057763079 | G14: =E14 -> V | H14: =DataSheet!L59+D14 -> 5.4408 | I14: =G14 -> V | J14: =DataSheet!L59-D14 -> 5.3592 | K14: =I14 -> V | L14: =IF(AND(B14<=H14,B14>=J14),"PASSED","FAILED") -> PASSED | N14: =F14+B14 -> 5.4005776 | O14: =G14 -> V | P14: =H14 -> 5.4408 | Q14: =O14 -> V | R14: =IF(AND(N14<=H14,N14>=J14),"PASSED","FAILED") -> PASSED | T14: =-DataSheet!DD59+B14 -> 5.3994224 | U14: =O14 -> V | V14: =IF(AND(T14<=H14,T14>=J14),"PASSED","FAILED") -> PASSED | X14: =IF(AND(L14="PASSED",R14="PASSED",V14="PASSED"),"PASSED",IF(L14="FAILED","FAILED","UNDETERMINED")) -> PASSED
B15: =DataSheet!AM60 -> -5.4 | C15: =DataSheet!P60 -> V | D15: =ABS((B15*0.7%)-(3*DataSheet!CK60)) -> 0.0408 | E15: =C15 -> V | F15: =DataSheet!DD60 -> 0.00057763079 | G15: =E15 -> V | H15: =DataSheet!L60+D15 -> -5.3592 | I15: =G15 -> V | J15: =DataSheet!L60-D15 -> -5.4408 | K15: =I15 -> V | L15: =IF(AND(B15<=H15,B15>=J15),"PASSED","FAILED") -> PASSED | N15: =F15+B15 -> -5.3994224 | O15: =G15 -> V | P15: =H15 -> -5.3592 | Q15: =O15 -> V | R15: =IF(AND(N15<=H15,N15>=J15),"PASSED","FAILED") -> PASSED | T15: =-DataSheet!DD60+B15 -> -5.4005776 | U15: =O15 -> V | V15: =IF(AND(T15<=H15,T15>=J15),"PASSED","FAILED") -> PASSED | X15: =IF(AND(L15="PASSED",R15="PASSED",V15="PASSED"),"PASSED",IF(L15="FAILED","FAILED","UNDETERMINED")) -> PASSED
B16: =DataSheet!AM61 -> 6 | C16: =DataSheet!P61 -> V | D16: =ABS((B16*0.7%)+(3*DataSheet!CK61)) -> 0.072 | E16: =C16 -> V | F16: =DataSheet!DD61 -> 0.0057735308 | G16: =E16 -> V | H16: =DataSheet!L61+D16 -> 6.072 | I16: =G16 -> V | J16: =DataSheet!L61-D16 -> 5.928 | K16: =I16 -> V | L16: =IF(AND(B16<=H16,B16>=J16),"PASSED","FAILED") -> PASSED | N16: =F16+B16 -> 6.0057735 | O16: =G16 -> V | P16: =H16 -> 6.072 | Q16: =O16 -> V | R16: =IF(AND(N16<=H16,N16>=J16),"PASSED","FAILED") -> PASSED | T16: =-F16+B16 -> 5.9942265 | U16: =O16 -> V | V16: =IF(AND(T16<=H16,T16>=J16),"PASSED","FAILED") -> PASSED | X16: =IF(AND(L16="PASSED",R16="PASSED",V16="PASSED"),"PASSED",IF(L16="FAILED","FAILED","UNDETERMINED")) -> PASSED
B17: =DataSheet!AM62 -> 30 | C17: =DataSheet!P62 -> V | D17: =ABS((B17*0.7%)+(3*DataSheet!CK62)) -> 0.24 | E17: =C17 -> V | F17: =DataSheet!DD62 -> 0.0057743687 | G17: =E17 -> V | H17: =DataSheet!L62+D17 -> 30.24 | I17: =G17 -> V | J17: =DataSheet!L62-D17 -> 29.76 | K17: =I17 -> V | L17: =IF(AND(B17<=H17,B17>=J17),"PASSED","FAILED") -> PASSED | N17: =F17+B17 -> 30.005774 | O17: =G17 -> V | P17: =H17 -> 30.24 | Q17: =O17 -> V | R17: =IF(AND(N17<=H17,N17>=J17),"PASSED","FAILED") -> PASSED | T17: =-F17+B17 -> 29.994226 | U17: =O17 -> V | V17: =IF(AND(T17<=H17,T17>=J17),"PASSED","FAILED") -> PASSED | X17: =IF(AND(L17="PASSED",R17="PASSED",V17="PASSED"),"PASSED",IF(L17="FAILED","FAILED","UNDETERMINED")) -> PASSED
B18: =DataSheet!AM63 -> 54 | C18: =DataSheet!P63 -> V | D18: =ABS((B18*0.7%)+(3*DataSheet!CK63)) -> 0.408 | E18: =C18 -> V | F18: =DataSheet!DD63 -> 0.0057818192 | G18: =E18 -> V | H18: =DataSheet!L63+D18 -> 54.408 | I18: =G18 -> V | J18: =DataSheet!L63-D18 -> 53.592 | K18: =I18 -> V | L18: =IF(AND(B18<=H18,B18>=J18),"PASSED","FAILED") -> PASSED | N18: =F18+B18 -> 54.005782 | O18: =G18 -> V | P18: =H18 -> 54.408 | Q18: =O18 -> V | R18: =IF(AND(N18<=H18,N18>=J18),"PASSED","FAILED") -> PASSED | T18: =-F18+B18 -> 53.994218 | U18: =O18 -> V | V18: =IF(AND(T18<=H18,T18>=J18),"PASSED","FAILED") -> PASSED | X18: =IF(AND(L18="PASSED",R18="PASSED",V18="PASSED"),"PASSED",IF(L18="FAILED","FAILED","UNDETERMINED")) -> PASSED
B19: =DataSheet!AM64 -> -6 | C19: =DataSheet!P64 -> V | D19: =ABS((B19*0.7%)-(3*DataSheet!CK64)) -> 0.072 | E19: =C19 -> V | F19: =DataSheet!DD64 -> 0.0057735308 | G19: =E19 -> V | H19: =DataSheet!L64+D19 -> -5.928 | I19: =G19 -> V | J19: =DataSheet!L64-D19 -> -6.072 | K19: =I19 -> V | L19: =IF(AND(B19<=H19,B19>=J19),"PASSED","FAILED") -> PASSED | N19: =F19+B19 -> -5.9942265 | O19: =G19 -> V | P19: =H19 -> -5.928 | Q19: =O19 -> V | R19: =IF(AND(N19<=H19,N19>=J19),"PASSED","FAILED") -> PASSED | T19: =-F19+B19 -> -6.0057735 | U19: =O19 -> V | V19: =IF(AND(T19<=H19,T19>=J19),"PASSED","FAILED") -> PASSED | X19: =IF(AND(L19="PASSED",R19="PASSED",V19="PASSED"),"PASSED",IF(L19="FAILED","FAILED","UNDETERMINED")) -> PASSED
B20: =DataSheet!AM65 -> -54 | C20: =DataSheet!P65 -> V | D20: =ABS((B20*0.7%)-(3*DataSheet!CK65)) -> 0.408 | E20: =C20 -> V | F20: =DataSheet!DD65 -> 0.0057818192 | G20: =E20 -> V | H20: =DataSheet!L65+D20 -> -53.592 | I20: =G20 -> V | J20: =DataSheet!L65-D20 -> -54.408 | K20: =I20 -> V | L20: =IF(AND(B20<=H20,B20>=J20),"PASSED","FAILED") -> PASSED | N20: =F20+B20 -> -53.994218 | O20: =G20 -> V | P20: =H20 -> -53.592 | Q20: =O20 -> V | R20: =IF(AND(N20<=H20,N20>=J20),"PASSED","FAILED") -> PASSED | T20: =-F20+B20 -> -54.005782 | U20: =O20 -> V | V20: =IF(AND(T20<=H20,T20>=J20),"PASSED","FAILED") -> PASSED | X20: =IF(AND(L20="PASSED",R20="PASSED",V20="PASSED"),"PASSED",IF(L20="FAILED","FAILED","UNDETERMINED")) -> PASSED
B21: =DataSheet!#REF! -> #REF! | C21: =DataSheet!#REF! -> #REF! | D21: =ABS((DataSheet!#REF!*0.7%)+(3*DataSheet!#REF!)) -> #REF! | E21: =C21 -> #REF! | F21: =DataSheet!#REF! -> #REF! | G21: =E21 -> #REF! | H21: =DataSheet!#REF!+D21 -> #REF! | I21: =G21 -> #REF! | J21: =DataSheet!#REF!-D21 -> #REF! | K21: =I21 -> #REF! | L21: =IF(AND(B21<=H21,B21>=J21),"PASSED","FAILED") -> #REF! | N21: =F21+B21 -> #REF! | O21: =G21 -> #REF! | P21: =H21 -> #REF! | Q21: =O21 -> #REF! | R21: =IF(AND(N21<=H21,N21>=J21),"PASSED","FAILED") -> #REF! | T21: =-F21+B21 -> #REF! | U21: =O21 -> #REF! | V21: =IF(AND(T21<=H21,T21>=J21),"PASSED","FAILED") -> #REF! | X21: =IF(AND(L21="PASSED",R21="PASSED",V21="PASSED"),"PASSED",IF(L21="FAILED","FAILED","UNDETERMINED")) -> #REF!
B22: =DataSheet!#REF! -> #REF! | C22: =DataSheet!#REF! -> #REF! | D22: =ABS((DataSheet!#REF!*0.7%)+(3*DataSheet!#REF!)) -> #REF! | E22: =C22 -> #REF! | F22: =DataSheet!#REF! -> #REF! | G22: =E22 -> #REF! | H22: =DataSheet!#REF!+D22 -> #REF! | I22: =G22 -> #REF! | J22: =DataSheet!#REF!-D22 -> #REF! | K22: =I22 -> #REF! | L22: =IF(AND(B22<=H22,B22>=J22),"PASSED","FAILED") -> #REF! | N22: =F22+B22 -> #REF! | O22: =G22 -> #REF! | P22: =H22 -> #REF! | Q22: =O22 -> #REF! | R22: =IF(AND(N22<=H22,N22>=J22),"PASSED","FAILED") -> #REF! | T22: =-F22+B22 -> #REF! | U22: =O22 -> #REF! | V22: =IF(AND(T22<=H22,T22>=J22),"PASSED","FAILED") -> #REF! | X22: =IF(AND(L22="PASSED",R22="PASSED",V22="PASSED"),"PASSED",IF(L22="FAILED","FAILED","UNDETERMINED")) -> #REF!
B23: =DataSheet!#REF! -> #REF! | C23: =DataSheet!#REF! -> #REF! | D23: =ABS((DataSheet!#REF!*0.7%)-(3*DataSheet!#REF!)) -> #REF! | E23: =C23 -> #REF! | F23: =DataSheet!#REF! -> #REF! | G23: =E23 -> #REF! | H23: =DataSheet!#REF!+D23 -> #REF! | I23: =G23 -> #REF! | J23: =DataSheet!#REF!-D23 -> #REF! | K23: =I23 -> #REF! | L23: =IF(AND(B23<=H23,B23>=J23),"PASSED","FAILED") -> #REF! | N23: =F23+B23 -> #REF! | O23: =G23 -> #REF! | P23: =H23 -> #REF! | Q23: =O23 -> #REF! | R23: =IF(AND(N23<=H23,N23>=J23),"PASSED","FAILED") -> #REF! | T23: =-F23+B23 -> #REF! | U23: =O23 -> #REF! | V23: =IF(AND(T23<=H23,T23>=J23),"PASSED","FAILED") -> #REF! | X23: =IF(AND(L23="PASSED",R23="PASSED",V23="PASSED"),"PASSED",IF(L23="FAILED","FAILED","UNDETERMINED")) -> #REF!
B24: =DataSheet!AM66 -> 60 | C24: =DataSheet!P66 -> V | D24: =ABS((DataSheet!AM66*0.7%)+(3*DataSheet!CK66)) -> 0.72 | E24: =C24 -> V | F24: =DataSheet!DD66 -> 0.057735859 | G24: =E24 -> V | H24: =DataSheet!L66+D24 -> 60.72 | I24: =G24 -> V | J24: =DataSheet!L66-D24 -> 59.28 | K24: =I24 -> V | L24: =IF(AND(B24<=H24,B24>=J24),"PASSED","FAILED") -> PASSED | N24: =F24+B24 -> 60.057736 | O24: =G24 -> V | P24: =H24 -> 60.72 | Q24: =O24 -> V | R24: =IF(AND(N24<=H24,N24>=J24),"PASSED","FAILED") -> PASSED | T24: =-F24+B24 -> 59.942264 | U24: =O24 -> V | V24: =IF(AND(T24<=H24,T24>=J24),"PASSED","FAILED") -> PASSED | X24: =IF(AND(L24="PASSED",R24="PASSED",V24="PASSED"),"PASSED",IF(L24="FAILED","FAILED","UNDETERMINED")) -> PASSED
B25: =DataSheet!AM67 -> 540 | C25: =DataSheet!P67 -> V | D25: =ABS((DataSheet!AM67*0.7%)+(3*DataSheet!CK67)) -> 4.08 | E25: =C25 -> V | F25: =DataSheet!DD67 -> 0.05782926 | G25: =E25 -> V | H25: =DataSheet!L67+D25 -> 544.08 | I25: =G25 -> V | J25: =DataSheet!L67-D25 -> 535.92 | K25: =I25 -> V | L25: =IF(AND(B25<=H25,B25>=J25),"PASSED","FAILED") -> PASSED | N25: =F25+B25 -> 540.05783 | O25: =G25 -> V | P25: =H25 -> 544.08 | Q25: =O25 -> V | R25: =IF(AND(N25<=H25,N25>=J25),"PASSED","FAILED") -> PASSED | T25: =-F25+B25 -> 539.94217 | U25: =O25 -> V | V25: =IF(AND(T25<=H25,T25>=J25),"PASSED","FAILED") -> PASSED | X25: =IF(AND(L25="PASSED",R25="PASSED",V25="PASSED"),"PASSED",IF(L25="FAILED","FAILED","UNDETERMINED")) -> PASSED
B26: =DataSheet!AM68 -> -540 | C26: =DataSheet!P68 -> V | D26: =ABS((DataSheet!AM68*0.7%)-(3*DataSheet!CK68)) -> 4.08 | E26: =C26 -> V | F26: =DataSheet!DD68 -> 0.05782926 | G26: =E26 -> V | H26: =DataSheet!L68+D26 -> -535.92 | I26: =G26 -> V | J26: =DataSheet!L68-D26 -> -544.08 | K26: =I26 -> V | L26: =IF(AND(B26<=H26,B26>=J26),"PASSED","FAILED") -> PASSED | N26: =F26+B26 -> -539.94217 | O26: =G26 -> V | P26: =H26 -> -535.92 | Q26: =O26 -> V | R26: =IF(AND(N26<=H26,N26>=J26),"PASSED","FAILED") -> PASSED | T26: =-F26+B26 -> -540.05783 | U26: =O26 -> V | V26: =IF(AND(T26<=H26,T26>=J26),"PASSED","FAILED") -> PASSED | X26: =IF(AND(L26="PASSED",R26="PASSED",V26="PASSED"),"PASSED",IF(L26="FAILED","FAILED","UNDETERMINED")) -> PASSED
B27: =DataSheet!F73 -> AC Voltage Test | X27: FINAL REMARKS
B29: Measured Value | D29: Tolerance | F29: Uncertainty | H29: Upper Limit | J29: Lower Limit | L29: Remarks | N29: Measured + Upper UNC | P29: Upper Limit | R29: Remarks | T29: Measured + Lower UNC | V29: Remarks
B31: =DataSheet!AM80 -> 0.6 | C31: =DataSheet!P80 -> V | D31: =ABS((DataSheet!AM80*1.6%)+(9*DataSheet!CK80)) -> 0.0186 | E31: =C31 -> V | F31: =DataSheet!DD80 -> 0.0010776982 | G31: =E31 -> V | H31: =DataSheet!L80+D31 -> 0.6186 | J31: =DataSheet!L80-D31 -> 0.5814 | L31: =IF(AND(B31<=H31,B31>=J31),"PASSED","FAILED") -> PASSED | N31: =DataSheet!DD80+B31 -> 0.6010777 | O31: =G31 -> V | P31: =H31 -> 0.6186 | Q31: =O31 -> V | R31: =IF(AND(N31<=H31,N31>=J31),"PASSED","FAILED") -> PASSED | T31: =-DataSheet!DD80+B31 -> 0.5989223 | U31: =O31 -> V | V31: =IF(AND(T31<=H31,T31>=J31),"PASSED","FAILED") -> PASSED | X31: =IF(AND(L31="PASSED",R31="PASSED",V31="PASSED"),"PASSED",IF(L31="FAILED","FAILED","UNDETERMINED")) -> PASSED
B32: =DataSheet!AM81 -> 0.6 | C32: =DataSheet!P81 -> V | D32: =ABS((DataSheet!AM81*1.6%)+(9*DataSheet!CK81)) -> 0.0186 | E32: =C32 -> V | F32: =DataSheet!DD81 -> 0.0010776982 | G32: =E32 -> V | H32: =DataSheet!L81+D32 -> 0.6186 | J32: =DataSheet!L81-D32 -> 0.5814 | L32: =IF(AND(B32<=H32,B32>=J32),"PASSED","FAILED") -> PASSED | N32: =DataSheet!DD81+B32 -> 0.6010777 | O32: =G32 -> V | P32: =H32 -> 0.6186 | Q32: =O32 -> V | R32: =IF(AND(N32<=H32,N32>=J32),"PASSED","FAILED") -> PASSED | T32: =-DataSheet!DD81+B32 -> 0.5989223 | U32: =O32 -> V | V32: =IF(AND(T32<=H32,T32>=J32),"PASSED","FAILED") -> PASSED | X32: =IF(AND(L32="PASSED",R32="PASSED",V32="PASSED"),"PASSED",IF(L32="FAILED","FAILED","UNDETERMINED")) -> PASSED
B33: =DataSheet!AM82 -> 5.4 | C33: =DataSheet!P82 -> V | D33: =ABS((DataSheet!AM82*1.6%)+(9*DataSheet!CK82)) -> 0.0954 | E33: =C33 -> V | F33: =DataSheet!DD82 -> 0.0073227955 | G33: =E33 -> V | H33: =DataSheet!L82+D33 -> 5.4954 | J33: =DataSheet!L82-D33 -> 5.3046 | L33: =IF(AND(B33<=H33,B33>=J33),"PASSED","FAILED") -> PASSED | N33: =DataSheet!DD82+B33 -> 5.4073228 | O33: =G33 -> V | P33: =H33 -> 5.4954 | Q33: =O33 -> V | R33: =IF(AND(N33<=H33,N33>=J33),"PASSED","FAILED") -> PASSED | T33: =-DataSheet!DD82+B33 -> 5.3926772 | U33: =O33 -> V | V33: =IF(AND(T33<=H33,T33>=J33),"PASSED","FAILED") -> PASSED | X33: =IF(AND(L33="PASSED",R33="PASSED",V33="PASSED"),"PASSED",IF(L33="FAILED","FAILED","UNDETERMINED")) -> PASSED
B34: =DataSheet!AM83 -> 5.4 | C34: =DataSheet!P83 -> V | D34: =ABS((DataSheet!AM83*1.6%)+(9*DataSheet!CK83)) -> 0.0954 | E34: =C34 -> V | F34: =DataSheet!DD83 -> 0.0073227955 | G34: =E34 -> V | H34: =DataSheet!L83+D34 -> 5.4954 | J34: =DataSheet!L83-D34 -> 5.3046 | L34: =IF(AND(B34<=H34,B34>=J34),"PASSED","FAILED") -> PASSED | N34: =DataSheet!DD83+B34 -> 5.4073228 | O34: =G34 -> V | P34: =H34 -> 5.4954 | Q34: =O34 -> V | R34: =IF(AND(N34<=H34,N34>=J34),"PASSED","FAILED") -> PASSED | T34: =-DataSheet!DD83+B34 -> 5.3926772 | U34: =O34 -> V | V34: =IF(AND(T34<=H34,T34>=J34),"PASSED","FAILED") -> PASSED | X34: =IF(AND(L34="PASSED",R34="PASSED",V34="PASSED"),"PASSED",IF(L34="FAILED","FAILED","UNDETERMINED")) -> PASSED
B35: =DataSheet!AM84 -> 6 | C35: =DataSheet!P84 -> V | D35: =ABS((DataSheet!AM84*1.6%)+(9*DataSheet!CK84)) -> 0.186 | E35: =C35 -> V | F35: =DataSheet!DD84 -> 0.0093071657 | G35: =E35 -> V | H35: =DataSheet!L84+D35 -> 6.186 | J35: =DataSheet!L84-D35 -> 5.814 | L35: =IF(AND(B35<=H35,B35>=J35),"PASSED","FAILED") -> PASSED | N35: =DataSheet!DD84+B35 -> 6.0093072 | O35: =G35 -> V | P35: =H35 -> 6.186 | Q35: =O35 -> V | R35: =IF(AND(N35<=H35,N35>=J35),"PASSED","FAILED") -> PASSED | T35: =-F35+B35 -> 5.9906928 | U35: =O35 -> V | V35: =IF(AND(T35<=H35,T35>=J35),"PASSED","FAILED") -> PASSED | X35: =IF(AND(L35="PASSED",R35="PASSED",V35="PASSED"),"PASSED",IF(L35="FAILED","FAILED","UNDETERMINED")) -> PASSED
B36: =DataSheet!AM85 -> 6 | C36: =DataSheet!P85 -> V | D36: =ABS((DataSheet!AM85*1.6%)+(9*DataSheet!CK85)) -> 0.186 | E36: =C36 -> V | F36: =DataSheet!DD85 -> 0.0093071657 | G36: =E36 -> V | H36: =DataSheet!L85+D36 -> 6.186 | J36: =DataSheet!L85-D36 -> 5.814 | L36: =IF(AND(B36<=H36,B36>=J36),"PASSED","FAILED") -> PASSED | N36: =DataSheet!DD85+B36 -> 6.0093072 | O36: =G36 -> V | P36: =H36 -> 6.186 | Q36: =O36 -> V | R36: =IF(AND(N36<=H36,N36>=J36),"PASSED","FAILED") -> PASSED | T36: =-F36+B36 -> 5.9906928 | U36: =O36 -> V | V36: =IF(AND(T36<=H36,T36>=J36),"PASSED","FAILED") -> PASSED | X36: =IF(AND(L36="PASSED",R36="PASSED",V36="PASSED"),"PASSED",IF(L36="FAILED","FAILED","UNDETERMINED")) -> PASSED
B37: =DataSheet!AM86 -> 30 | C37: =DataSheet!P86 -> V | D37: =ABS((DataSheet!AM86*1.6%)+(9*DataSheet!CK86)) -> 0.57 | E37: =C37 -> V | F37: =DataSheet!DD86 -> 0.0093071657 | G37: =E37 -> V | H37: =DataSheet!L86+D37 -> 30.57 | J37: =DataSheet!L86-D37 -> 29.43 | L37: =IF(AND(B37<=H37,B37>=J37),"PASSED","FAILED") -> PASSED | N37: =DataSheet!DD86+B37 -> 30.009307 | O37: =G37 -> V | P37: =H37 -> 30.57 | Q37: =O37 -> V | R37: =IF(AND(N37<=H37,N37>=J37),"PASSED","FAILED") -> PASSED | T37: =-F37+B37 -> 29.990693 | U37: =O37 -> V | V37: =IF(AND(T37<=H37,T37>=J37),"PASSED","FAILED") -> PASSED | X37: =IF(AND(L37="PASSED",R37="PASSED",V37="PASSED"),"PASSED",IF(L37="FAILED","FAILED","UNDETERMINED")) -> PASSED
B38: =DataSheet!AM87 -> 30 | C38: =DataSheet!P87 -> V | D38: =ABS((DataSheet!AM87*1.6%)+(9*DataSheet!CK87)) -> 0.57 | E38: =C38 -> V | F38: =DataSheet!DD87 -> 0.0093071657 | G38: =E38 -> V | H38: =DataSheet!L87+D38 -> 30.57 | J38: =DataSheet!L87-D38 -> 29.43 | L38: =IF(AND(B38<=H38,B38>=J38),"PASSED","FAILED") -> PASSED | N38: =DataSheet!DD87+B38 -> 30.009307 | O38: =G38 -> V | P38: =H38 -> 30.57 | Q38: =O38 -> V | R38: =IF(AND(N38<=H38,N38>=J38),"PASSED","FAILED") -> PASSED | T38: =-F38+B38 -> 29.990693 | U38: =O38 -> V | V38: =IF(AND(T38<=H38,T38>=J38),"PASSED","FAILED") -> PASSED | X38: =IF(AND(L38="PASSED",R38="PASSED",V38="PASSED"),"PASSED",IF(L38="FAILED","FAILED","UNDETERMINED")) -> PASSED
B39: =DataSheet!AM88 -> 54 | C39: =DataSheet!P88 -> V | D39: =ABS((DataSheet!AM88*1.6%)+(9*DataSheet!CK88)) -> 0.954 | E39: =C39 -> V | F39: =DataSheet!DD88 -> 0.071234355 | G39: =E39 -> V | H39: =DataSheet!L88+D39 -> 54.954 | J39: =DataSheet!L88-D39 -> 53.046 | L39: =IF(AND(B39<=H39,B39>=J39),"PASSED","FAILED") -> PASSED | N39: =DataSheet!DD88+B39 -> 54.071234 | O39: =G39 -> V | P39: =H39 -> 54.954 | Q39: =O39 -> V | R39: =IF(AND(N39<=H39,N39>=J39),"PASSED","FAILED") -> PASSED | T39: =-F39+B39 -> 53.928766 | U39: =O39 -> V | V39: =IF(AND(T39<=H39,T39>=J39),"PASSED","FAILED") -> PASSED | X39: =IF(AND(L39="PASSED",R39="PASSED",V39="PASSED"),"PASSED",IF(L39="FAILED","FAILED","UNDETERMINED")) -> PASSED
B40: =DataSheet!AM89 -> 54 | C40: =DataSheet!P89 -> V | D40: =ABS((DataSheet!AM89*1.6%)+(9*DataSheet!CK89)) -> 0.954 | E40: =C40 -> V | F40: =DataSheet!DD89 -> 0.071234355 | G40: =E40 -> V | H40: =DataSheet!L89+D40 -> 54.954 | J40: =DataSheet!L89-D40 -> 53.046 | L40: =IF(AND(B40<=H40,B40>=J40),"PASSED","FAILED") -> PASSED | N40: =DataSheet!DD89+B40 -> 54.071234 | O40: =G40 -> V | P40: =H40 -> 54.954 | Q40: =O40 -> V | R40: =IF(AND(N40<=H40,N40>=J40),"PASSED","FAILED") -> PASSED | T40: =-F40+B40 -> 53.928766 | U40: =O40 -> V | V40: =IF(AND(T40<=H40,T40>=J40),"PASSED","FAILED") -> PASSED | X40: =IF(AND(L40="PASSED",R40="PASSED",V40="PASSED"),"PASSED",IF(L40="FAILED","FAILED","UNDETERMINED")) -> PASSED
B41: =DataSheet!#REF! -> #REF! | C41: =DataSheet!#REF! -> #REF! | D41: =ABS((DataSheet!#REF!*1.6%)+(9*DataSheet!#REF!)) -> #REF! | E41: =C41 -> #REF! | F41: =DataSheet!#REF! -> #REF! | G41: =E41 -> #REF! | H41: =DataSheet!#REF!+D41 -> #REF! | J41: =DataSheet!#REF!-D41 -> #REF! | L41: =IF(AND(B41<=H41,B41>=J41),"PASSED","FAILED") -> #REF! | N41: =DataSheet!#REF!+B41 -> #REF! | O41: =G41 -> #REF! | P41: =H41 -> #REF! | Q41: =O41 -> #REF! | R41: =IF(AND(N41<=H41,N41>=J41),"PASSED","FAILED") -> #REF! | T41: =-F41+B41 -> #REF! | U41: =O41 -> #REF! | V41: =IF(AND(T41<=H41,T41>=J41),"PASSED","FAILED") -> #REF! | X41: =IF(AND(L41="PASSED",R41="PASSED",V41="PASSED"),"PASSED",IF(L41="FAILED","FAILED","UNDETERMINED")) -> #REF!
B42: =DataSheet!#REF! -> #REF! | C42: =DataSheet!#REF! -> #REF! | D42: =ABS((DataSheet!#REF!*1.6%)+(9*DataSheet!#REF!)) -> #REF! | E42: =C42 -> #REF! | F42: =DataSheet!#REF! -> #REF! | G42: =E42 -> #REF! | H42: =DataSheet!#REF!+D42 -> #REF! | J42: =DataSheet!#REF!-D42 -> #REF! | L42: =IF(AND(B42<=H42,B42>=J42),"PASSED","FAILED") -> #REF! | N42: =DataSheet!#REF!+B42 -> #REF! | O42: =G42 -> #REF! | P42: =H42 -> #REF! | Q42: =O42 -> #REF! | R42: =IF(AND(N42<=H42,N42>=J42),"PASSED","FAILED") -> #REF! | T42: =-F42+B42 -> #REF! | U42: =O42 -> #REF! | V42: =IF(AND(T42<=H42,T42>=J42),"PASSED","FAILED") -> #REF! | X42: =IF(AND(L42="PASSED",R42="PASSED",V42="PASSED"),"PASSED",IF(L42="FAILED","FAILED","UNDETERMINED")) -> #REF!
B43: =DataSheet!#REF! -> #REF! | C43: =DataSheet!#REF! -> #REF! | D43: =ABS((DataSheet!#REF!*1.6%)+(9*DataSheet!#REF!)) -> #REF! | E43: =C43 -> #REF! | F43: =DataSheet!#REF! -> #REF! | G43: =E43 -> #REF! | H43: =DataSheet!#REF!+D43 -> #REF! | J43: =DataSheet!#REF!-D43 -> #REF! | L43: =IF(AND(B43<=H43,B43>=J43),"PASSED","FAILED") -> #REF! | N43: =DataSheet!#REF!+B43 -> #REF! | O43: =G43 -> #REF! | P43: =H43 -> #REF! | Q43: =O43 -> #REF! | R43: =IF(AND(N43<=H43,N43>=J43),"PASSED","FAILED") -> #REF! | T43: =-F43+B43 -> #REF! | U43: =O43 -> #REF! | V43: =IF(AND(T43<=H43,T43>=J43),"PASSED","FAILED") -> #REF! | X43: =IF(AND(L43="PASSED",R43="PASSED",V43="PASSED"),"PASSED",IF(L43="FAILED","FAILED","UNDETERMINED")) -> #REF!
B44: =DataSheet!#REF! -> #REF! | C44: =DataSheet!#REF! -> #REF! | D44: =ABS((DataSheet!#REF!*1.6%)+(9*DataSheet!#REF!)) -> #REF! | E44: =C44 -> #REF! | F44: =DataSheet!#REF! -> #REF! | G44: =E44 -> #REF! | H44: =DataSheet!#REF!+D44 -> #REF! | J44: =DataSheet!#REF!-D44 -> #REF! | L44: =IF(AND(B44<=H44,B44>=J44),"PASSED","FAILED") -> #REF! | N44: =DataSheet!#REF!+B44 -> #REF! | O44: =G44 -> #REF! | P44: =H44 -> #REF! | Q44: =O44 -> #REF! | R44: =IF(AND(N44<=H44,N44>=J44),"PASSED","FAILED") -> #REF! | T44: =-F44+B44 -> #REF! | U44: =O44 -> #REF! | V44: =IF(AND(T44<=H44,T44>=J44),"PASSED","FAILED") -> #REF! | X44: =IF(AND(L44="PASSED",R44="PASSED",V44="PASSED"),"PASSED",IF(L44="FAILED","FAILED","UNDETERMINED")) -> #REF!
B45: =DataSheet!AM90 -> 60 | C45: =DataSheet!P90 -> V | D45: =ABS((DataSheet!AM90*1.6%)+(9*DataSheet!CK90)) -> 1.86 | E45: =C45 -> V | F45: =DataSheet!DD90 -> 0.091511384 | G45: =E45 -> V | H45: =DataSheet!L90+D45 -> 61.86 | J45: =DataSheet!L90-D45 -> 58.14 | L45: =IF(AND(B45<=H45,B45>=J45),"PASSED","FAILED") -> PASSED | N45: =DataSheet!DD90+B45 -> 60.091511 | O45: =G45 -> V | P45: =H45 -> 61.86 | Q45: =O45 -> V | R45: =IF(AND(N45<=H45,N45>=J45),"PASSED","FAILED") -> PASSED | T45: =-F45+B45 -> 59.908489 | U45: =O45 -> V | V45: =IF(AND(T45<=H45,T45>=J45),"PASSED","FAILED") -> PASSED | X45: =IF(AND(L45="PASSED",R45="PASSED",V45="PASSED"),"PASSED",IF(L45="FAILED","FAILED","UNDETERMINED")) -> PASSED
B46: =DataSheet!AM91 -> 60 | C46: =DataSheet!P91 -> V | D46: =ABS((DataSheet!AM91*1.6%)+(9*DataSheet!CK91)) -> 1.86 | E46: =C46 -> V | F46: =DataSheet!DD91 -> 0.091511384 | G46: =E46 -> V | H46: =DataSheet!L91+D46 -> 61.86 | J46: =DataSheet!L91-D46 -> 58.14 | L46: =IF(AND(B46<=H46,B46>=J46),"PASSED","FAILED") -> PASSED | N46: =DataSheet!DD91+B46 -> 60.091511 | O46: =G46 -> V | P46: =H46 -> 61.86 | Q46: =O46 -> V | R46: =IF(AND(N46<=H46,N46>=J46),"PASSED","FAILED") -> PASSED | T46: =-F46+B46 -> 59.908489 | U46: =O46 -> V | V46: =IF(AND(T46<=H46,T46>=J46),"PASSED","FAILED") -> PASSED | X46: =IF(AND(L46="PASSED",R46="PASSED",V46="PASSED"),"PASSED",IF(L46="FAILED","FAILED","UNDETERMINED")) -> PASSED
B47: =DataSheet!AM92 -> 540 | C47: =DataSheet!P92 -> V | D47: =ABS((DataSheet!AM92*1.6%)+(9*DataSheet!CK92)) -> 9.54 | E47: =C47 -> V | F47: =DataSheet!DD92 -> 0.091511384 | G47: =E47 -> V | H47: =DataSheet!L92+D47 -> 549.54 | J47: =DataSheet!L92-D47 -> 530.46 | L47: =IF(AND(B47<=H47,B47>=J47),"PASSED","FAILED") -> PASSED | N47: =DataSheet!DD92+B47 -> 540.09151 | O47: =G47 -> V | P47: =H47 -> 549.54 | Q47: =O47 -> V | R47: =IF(AND(N47<=H47,N47>=J47),"PASSED","FAILED") -> PASSED | T47: =-F47+B47 -> 539.90849 | U47: =O47 -> V | V47: =IF(AND(T47<=H47,T47>=J47),"PASSED","FAILED") -> PASSED | X47: =IF(AND(L47="PASSED",R47="PASSED",V47="PASSED"),"PASSED",IF(L47="FAILED","FAILED","UNDETERMINED")) -> PASSED
...

Sheet Specification
